Workbook

Sheet Monthly Summary
A1: Month | B1: Period | C1: Canada | D1: Total | E1: Strong matches | F1: Global North | G1: Global South
A2: 2024-01 | B2: Pre-withdrawal | C2: =COUNTIFS('All Articles'!$A:$A,$A2,'All Articles'!$D:$D,C$1) | D2: =SUM(C2:C2) | E2: =COUNTIFS('All Articles'!$A:$A,$A2,'All Articles'!$M:$M,"Yes") | F2: =COUNTIFS('All Articles'!$A:$A,$A2,'All Articles'!$E:$E,"Global North") | G2: =COUNTIFS('All Articles'!$A:$A,$A2,'All Articles'!$E:$E,"Global South")
A3: 2024-02 | B3: Pre-withdrawal | C3: =COUNTIFS('All Articles'!$A:$A,$A3,'All Articles'!$D:$D,C$1) | D3: =SUM(C3:C3) | E3: =COUNTIFS('All Articles'!$A:$A,$A3,'All Articles'!$M:$M,"Yes") | F3: =COUNTIFS('All Articles'!$A:$A,$A3,'All Articles'!$E:$E,"Global North") | G3: =COUNTIFS('All Articles'!$A:$A,$A3,'All Articles'!$E:$E,"Global South")
A4: 2024-03 | B4: Pre-withdrawal | C4: =COUNTIFS('All Articles'!$A:$A,$A4,'All Articles'!$D:$D,C$1) | D4: =SUM(C4:C4) | E4: =COUNTIFS('All Articles'!$A:$A,$A4,'All Articles'!$M:$M,"Yes") | F4: =COUNTIFS('All Articles'!$A:$A,$A4,'All Articles'!$E:$E,"Global North") | G4: =COUNTIFS('All Articles'!$A:$A,$A4,'All Articles'!$E:$E,"Global South")
A5: 2024-04 | B5: Pre-withdrawal | C5: =COUNTIFS('All Articles'!$A:$A,$A5,'All Articles'!$D:$D,C$1) | D5: =SUM(C5:C5) | E5: =COUNTIFS('All Articles'!$A:$A,$A5,'All Articles'!$M:$M,"Yes") | F5: =COUNTIFS('All Articles'!$A:$A,$A5,'All Articles'!$E:$E,"Global North") | G5: =COUNTIFS('All Articles'!$A:$A,$A5,'All Articles'!$E:$E,"Global South")
A6: 2024-05 | B6: Pre-withdrawal | C6: =COUNTIFS('All Articles'!$A:$A,$A6,'All Articles'!$D:$D,C$1) | D6: =SUM(C6:C6) | E6: =COUNTIFS('All Articles'!$A:$A,$A6,'All Articles'!$M:$M,"Yes") | F6: =COUNTIFS('All Articles'!$A:$A,$A6,'All Articles'!$E:$E,"Global North") | G6: =COUNTIFS('All Articles'!$A:$A,$A6,'All Articles'!$E:$E,"Global South")
A7: 2024-06 | B7: Pre-withdrawal | C7: =COUNTIFS('All Articles'!$A:$A,$A7,'All Articles'!$D:$D,C$1) | D7: =SUM(C7:C7) | E7: =COUNTIFS('All Articles'!$A:$A,$A7,'All Articles'!$M:$M,"Yes") | F7: =COUNTIFS('All Articles'!$A:$A,$A7,'All Articles'!$E:$E,"Global North") | G7: =COUNTIFS('All Articles'!$A:$A,$A7,'All Articles'!$E:$E,"Global South")
A8: 2024-07 | B8: Pre-withdrawal | C8: =COUNTIFS('All Articles'!$A:$A,$A8,'All Articles'!$D:$D,C$1) | D8: =SUM(C8:C8) | E8: =COUNTIFS('All Articles'!$A:$A,$A8,'All Articles'!$M:$M,"Yes") | F8: =COUNTIFS('All Articles'!$A:$A,$A8,'All Articles'!$E:$E,"Global North") | G8: =COUNTIFS('All Articles'!$A:$A,$A8,'All Articles'!$E:$E,"Global South")
A9: 2024-08 | B9: Pre-withdrawal | C9: =COUNTIFS('All Articles'!$A:$A,$A9,'All Articles'!$D:$D,C$1) | D9: =SUM(C9:C9) | E9: =COUNTIFS('All Articles'!$A:$A,$A9,'All Articles'!$M:$M,"Yes") | F9: =COUNTIFS('All Articles'!$A:$A,$A9,'All Articles'!$E:$E,"Global North") | G9: =COUNTIFS('All Articles'!$A:$A,$A9,'All Articles'!$E:$E,"Global South")
A10: 2024-09 | B10: Pre-withdrawal | C10: =COUNTIFS('All Articles'!$A:$A,$A10,'All Articles'!$D:$D,C$1) | D10: =SUM(C10:C10) | E10: =COUNTIFS('All Articles'!$A:$A,$A10,'All Articles'!$M:$M,"Yes") | F10: =COUNTIFS('All Articles'!$A:$A,$A10,'All Articles'!$E:$E,"Global North") | G10: =COUNTIFS('All Articles'!$A:$A,$A10,'All Articles'!$E:$E,"Global South")
A11: 2024-10 | B11: Pre-withdrawal | C11: =COUNTIFS('All Articles'!$A:$A,$A11,'All Articles'!$D:$D,C$1) | D11: =SUM(C11:C11) | E11: =COUNTIFS('All Articles'!$A:$A,$A11,'All Articles'!$M:$M,"Yes") | F11: =COUNTIFS('All Articles'!$A:$A,$A11,'All Articles'!$E:$E,"Global North") | G11: =COUNTIFS('All Articles'!$A:$A,$A11,'All Articles'!$E:$E,"Global South")
A12: 2024-11 | B12: Pre-withdrawal | C12: =COUNTIFS('All Articles'!$A:$A,$A12,'All Articles'!$D:$D,C$1) | D12: =SUM(C12:C12) | E12: =COUNTIFS('All Articles'!$A:$A,$A12,'All Articles'!$M:$M,"Yes") | F12: =COUNTIFS('All Articles'!$A:$A,$A12,'All Articles'!$E:$E,"Global North") | G12: =COUNTIFS('All Articles'!$A:$A,$A12,'All Articles'!$E:$E,"Global South")
A13: 2024-12 | B13: Pre-withdrawal | C13: =COUNTIFS('All Articles'!$A:$A,$A13,'All Articles'!$D:$D,C$1) | D13: =SUM(C13:C13) | E13: =COUNTIFS('All Articles'!$A:$A,$A13,'All Articles'!$M:$M,"Yes") | F13: =COUNTIFS('All Articles'!$A:$A,$A13,'All Articles'!$E:$E,"Global North") | G13: =COUNTIFS('All Articles'!$A:$A,$A13,'All Articles'!$E:$E,"Global South")
... A30: 2026-05 | B30: Post-withdrawal | C30: =COUNTIFS('All Articles'!$A:$A,$A30,'All Articles'!$D:$D,C$1) | D30: =SUM(C30:C30) | E30: =COUNTIFS('All Articles'!$A:$A,$A30,'All Articles'!$M:$M,"Yes") | F30: =COUNTIFS('All Articles'!$A:$A,$A30,'All Articles'!$E:$E,"Global North") | G30: =COUNTIFS('All Articles'!$A:$A,$A30,'All Articles'!$E:$E,"Global South")
A31: Total | C31: =SUM(C2:C30) | D31: =SUM(D2:D30) | E31: =SUM(E2:E30) | F31: =SUM(F2:F30) | G31: =SUM(G2:G30)
A33: Undated articles | C33: =COUNTIFS('All Articles'!$A:$A,"Undated")
A35: Period | C35: Canada | D35: Total
A36: Pre-withdrawal | C36: =COUNTIFS('All Articles'!$C:$C,$A36,'All Articles'!$D:$D,C$35) | D36: =SUM(C36:C36)
A37: Transition | C37: =COUNTIFS('All Articles'!$C:$C,$A37,'All Articles'!$D:$D,C$35) | D37: =SUM(C37:C37)
A38: Post-withdrawal | C38: =COUNTIFS('All Articles'!$C:$C,$A38,'All Articles'!$D:$D,C$35) | D38: =SUM(C38:C38)
A40: Shaded cells = no articles collected for that country in that month (a coverage gap).

Sheet All Articles
A1: Month | B1: Date | C1: Period | D1: Country | E1: North/South | F1: Continent | G1: Source Type | H1: Document Type | I1: Site | J1: Title | K1: URL | L1: Matched Keywords | M1: Strong Match | N1: Keyword Count | O1: Minister/Person Country | P1: Date Source | Q1: Fetched Via | R1: Word Count | S1: Event/Person hits | T1: Adjective Indicators hits | U1: Organizations/Alliances hits | V1: Regulatory Bodies hits
A2: 2024-01 | B2: 45293 | C2: Pre-withdrawal | D2: Canada | E2: Global North | F2: North America | G2: Ministry of Environment | H2: Press release | I2: canada.ca | J2: The Government of Canada is seeking feedback on developing a federal plastics registry to help tackle plastic pollution | K2: https://www.canada.ca/en/environment-climate-change/news/2024/01/the-government-of-canada-is-seeking-feedback-on-developing-a-federal-plastics-registry-to-help-tackle-plastic-pollution.html | L2: Circular; Circular Economy; Climate; Climate Change; Environment; Steven Guilbeault; transition | M2: Yes | N2: 7 | O2: Canada | P2: page metadata | Q2: live | R2: 733 | S2: Steven Guilbeault | T2: Circular; Circular Economy; Climate; Climate Change; Environment; transition
A3: 2024-01 | B3: 45302 | C3: Pre-withdrawal | D3: Canada | E3: Global North | F3: North America | G3: Ministry of Environment | H3: Press release | I3: canada.ca | J3: Environment and Climate Change Canada to hold a technical briefing and media availability related to a winter storm affecting Ontario and Quebec this weekend | K3: https://www.canada.ca/en/environment-climate-change/news/2024/01/environment-and-climate-change-canada-to-hold-a-technical-briefing-and-media-availability-related-to-a-winter-storm-affecting-ontario-and-quebec-th.html | L3: Climate; Climate Change; Environment | M3: No | N3: 3 | P3: page metadata | Q3: live | R3: 223 | T3: Climate; Climate Change; Environment
A4: 2024-01 | B4: 45303 | C4: Pre-withdrawal | D4: Canada | E4: Global North | F4: North America | G4: Ministry of Environment | H4: Press release | I4: canada.ca | J4: Eligible Canadian residents to receive their first pollution pricing rebate of the year | K4: https://www.canada.ca/en/environment-climate-change/news/2024/01/eligible-canadian-residents-to-receive-their-first-pollution-pricing-rebate-of-the-year.html | L4: Climate; Climate Change; Environment; Steven Guilbeault; carbon; emissions; energy; net zero emissions | M4: Yes | N4: 8 | O4: Canada | P4: page metadata | Q4: live | R4: 880 | S4: Steven Guilbeault | T4: Climate; Climate Change; Environment; carbon; emissions; energy; net zero emissions
A5: 2024-01 | B5: 45303 | C5: Pre-withdrawal | D5: Canada | E5: Global North | F5: North America | G5: Ministry of Environment | H5: Press release | I5: canada.ca | J5: Minister Guilbeault to make an announcement to support the Université de Sherbrooke’s work on environmental research | K5: https://www.canada.ca/en/environment-climate-change/news/2024/01/minister-guilbeault-to-make-an-announcement-to-support-the-universite-de-sherbrookes-work-on-environmental-research.html | L5: Climate; Climate Change; Environment; Steven Guilbeault | M5: Yes | N5: 4 | O5: Canada | P5: page metadata | Q5: live | R5: 196 | S5: Steven Guilbeault | T5: Climate; Climate Change; Environment
A6: 2024-01 | B6: 45306 | C6: Pre-withdrawal | D6: Canada | E6: Global North | F6: North America | G6: Ministry of Environment | H6: Press release | I6: canada.ca | J6: Government of Canada announces new investments in environmental research for the Université de Sherbrooke | K6: https://www.canada.ca/en/environment-climate-change/news/2024/01/government-of-canada-announces-new-investments-in-environmental-research-for-the-universite-de-sherbrooke.html | L6: Climate; Climate Change; Environment; Environmental Policy; Steven Guilbeault; carbon; emissions; greenhouse gas | M6: Yes | N6: 8 | O6: Canada | P6: page metadata | Q6: live | R6: 1074 | S6: Steven Guilbeault | T6: Climate; Climate Change; Environment; Environmental Policy; carbon; emissions; greenhouse gas
A7: 2024-01 | B7: 45310 | C7: Pre-withdrawal | D7: Canada | E7: Global North | F7: North America | G7: Ministry of Environment | H7: Press release | I7: canada.ca | J7: Government of Canada to make an announcement on funding for freshwater ecosystem initiatives | K7: https://www.canada.ca/en/environment-climate-change/news/2024/01/government-of-canada-to-make-an-announcement-on-funding-for-freshwater-ecosystem-initiatives.html | L7: Climate; Climate Change; Environment; Steven Guilbeault | M7: Yes | N7: 4 | O7: Canada | P7: page metadata | Q7: live | R7: 159 | S7: Steven Guilbeault | T7: Climate; Climate Change; Environment
A8: 2024-01 | B8: 45313 | C8: Pre-withdrawal | D8: Canada | E8: Global North | F8: North America | G8: Ministry of Environment | H8: Press release | I8: canada.ca | J8: Federal Government opens the door to projects that help keep Canadian fresh water clean and healthy | K8: https://www.canada.ca/en/environment-climate-change/news/2024/01/federal-government-opens-the-door-to-projects-that-help-keep-canadian-fresh-water-clean-and-healthy.html | L8: Climate; Climate Change; Environment; Steven Guilbeault | M8: Yes | N8: 4 | O8: Canada | P8: page metadata | Q8: live | R8: 1070 | S8: Steven Guilbeault | T8: Climate; Climate Change; Environment
A9: 2024-01 | B9: 45313 | C9: Pre-withdrawal | D9: Canada | E9: Global North | F9: North America | G9: Ministry of Environment | H9: Press release | I9: canada.ca | J9: Operation Northern Fur leads to $20,000 in fines and a prohibition order for a Manitoba resident who illegally imported, exported, and transported wildlife | K9: https://www.canada.ca/en/environment-climate-change/news/2024/01/operation-northern-fur-leads-to-20000-in-fines-and-a-prohibition-order-for-a-manitoba-resident-who-illegally-imported-exported-and-transported-wild.html | L9: Climate; Climate Change; Environment | M9: No | N9: 3 | P9: page metadata | Q9: live | R9: 619 | T9: Climate; Climate Change; Environment
A10: 2024-01 | B10: 45317 | C10: Pre-withdrawal | D10: Canada | E10: Global North | F10: North America | G10: Ministry of Environment | H10: Press release | I10: canada.ca | J10: Canada boosts conservation and restoration efforts with investments in 27 new Indigenous-Led Natural Climate Solutions | K10: https://www.canada.ca/en/environment-climate-change/news/2024/01/canada-boosts-conservation-and-restoration-efforts-with-investments-in-27-new-indigenous-led-natural-climate-solutions.html | L10: Climate; Climate Change; Environment; Steven Guilbeault; Sustainability; carbon; emissions; greenhouse gas | M10: Yes | N10: 8 | O10: Canada | P10: page metadata | Q10: live | R10: 1021 | S10: Steven Guilbeault | T10: Climate; Climate Change; Environment; Sustainability; carbon; emissions; greenhouse gas
A11: 2024-01 | B11: 45317 | C11: Pre-withdrawal | D11: Canada | E11: Global North | F11: North America | G11: Ministry of Environment | H11: Press release | I11: canada.ca | J11: List of 27 Indigenous-Led Natural Climate Solutions projects 2023–2024 | K11: https://www.canada.ca/en/environment-climate-change/news/2024/01/list-of-27-indigenous-led-natural-climate-solutions-projects-20232024.html | L11: Climate; Climate Change; Climate change mitigation; carbon; emissions; greenhouse gas | M11: Yes | N11: 6 | P11: page metadata | Q11: live | R11: 1927 | T11: Climate; Climate Change; Climate change mitigation; carbon; emissions; greenhouse gas
A12: 2024-01 | B12: 45317 | C12: Pre-withdrawal | D12: Canada | E12: Global North | F12: North America | G12: Ministry of Environment | H12: Policy / regulatory | I12: canada.ca | J12: North West Redwater Partnership paid $280,428 to the Environmental Damages Fund as part of an environmental protection alternative measures agreement under the Canadian Environmental Protection Act, 1999 | K12: https://www.canada.ca/en/environment-climate-change/news/2024/01/north-west-redwater-partnership-paid-280428-to-the-environmental-damages-fund-as-part-of-an-environmental-protection-alternative-measures-agreement.html | L12: Climate; Climate Change; Environment | M12: No | N12: 3 | P12: page metadata | Q12: live | R12: 691 | T12: Climate; Climate Change; Environment
A13: 2024-01 | B13: 45321 | C13: Pre-withdrawal | D13: Canada | E13: Global North | F13: North America | G13: Ministry of Environment | H13: Press release | I13: canada.ca | J13: Environment and Climate Change Canada Study of Winter Air Pollution in Toronto begins | K13: https://www.canada.ca/en/environment-climate-change/news/2024/01/environment-and-climate-change-canada-study-of-winter-air-pollution-in-toronto-begins.html | L13: Climate; Climate Change; Environment; carbon | M13: Yes | N13: 4 | P13: page metadata | Q13: live | R13: 570 | T13: Climate; Climate Change; Environment; carbon
A14: 2024-01 | B14: 45321 | C14: Pre-withdrawal | D14: Canada | E14: Global North | F14: North America | G14: Ministry of Environment | H14: Press release | I14: canada.ca | J14: Two Quebecers convicted of violating the Migratory Birds Regulations by destroying the nests of endangered Bank Swallows | K14: https://www.canada.ca/en/environment-climate-change/news/2024/01/two-quebecers-convicted-of-violating-the-migratory-birds-regulations-by-destroying-the-nests-of-endangered-bank-swallows.html | L14: Climate; Climate Change; Environment | M14: No | N14: 3 | P14: page metadata | Q14: live | R14: 485 | T14: Climate; Climate Change; Environment
A15: 2024-01 | B15: 45322 | C15: Pre-withdrawal | D15: Canada | E15: Global North | F15: North America | G15: Ministry of Environment | H15: Press release | I15: canada.ca | J15: Forty-two Indigenous-led conservation projects across Canada receive federal funding to protect more nature | K15: https://www.canada.ca/en/environment-climate-change/news/2024/01/forty-two-indigenous-led-conservation-projects-across-canada-receive-federal-funding-to-protect-more-nature.html | L15: Climate; Climate Change; Environment; Steven Guilbeault; Sustainability | M15: Yes | N15: 5 | O15: Canada | P15: page metadata | Q15: live | R15: 1284 | S15: Steven Guilbeault | T15: Climate; Climate Change; Environment; Sustainability
A16: 2024-02 | B16: 45324 | C16: Pre-withdrawal | D16: Canada | E16: Global North | F16: North America | G16: Ministry of Environment | H16: Press release | I16: canada.ca | J16: Government of Canada launches public engagement on the 2035 greenhouse gas emissions reduction target | K16: https://www.canada.ca/en/environment-climate-change/news/2024/02/government-of-canada-launches-public-engagement-on-the-2035-greenhouse-gas-emissions-reduction-target.html | L16: Climate; Climate Change; Environment; Paris Agreement; Steven Guilbeault; climate goals; emissions; energy; greenhouse gas; net zero emissions | M16: Yes | N16: 10 | O16: Canada | P16: page metadata | Q16: live | R16: 782 | S16: Steven Guilbeault | T16: Climate; Climate Change; Environment; climate goals; emissions; energy; greenhouse gas; net zero emissions | U16: Paris Agreement
A17: 2024-02 | B17: 45330 | C17: Pre-withdrawal | D17: Canada | E17: Global North | F17: North America | G17: Ministry of Environment | H17: Press release | I17: canada.ca | J17: Canada taking next steps on the right to a healthy environment and environmental justice and racism | K17: https://www.canada.ca/en/environment-climate-change/news/2024/02/canada-taking-next-steps-on-the-right-to-a-healthy-environment-and-environmental-justice-and-racism.html | L17: Climate; Climate Change; Environment | M17: No | N17: 3 | P17: page metadata | Q17: live | R17: 485 | T17: Climate; Climate Change; Environment
A18: 2024-02 | B18: 45330 | C18: Pre-withdrawal | D18: Canada | E18: Global North | F18: North America | G18: Ministry of Environment | H18: Policy / regulatory | I18: canada.ca | J18: Creating a healthy, clean, and sustainable environment for all: Canada consulting on the right to a healthy environment in federal legislation and engaging on environmental justice and racism | K18: https://www.canada.ca/en/environment-climate-change/news/2024/02/creating-a-healthy-clean-and-sustainable-environment-for-all-canada-consulting-on-the-right-to-a-healthy-environment-in-federal-legislation-and-eng.html | L18: Climate; Climate Change; Environment; Steven Guilbeault | M18: Yes | N18: 4 | O18: Canada | P18: page metadata | Q18: live | R18: 776 | S18: Steven Guilbeault | T18: Climate; Climate Change; Environment
A19: 2024-02 | B19: 45335 | C19: Pre-withdrawal | D19: Canada | E19: Global North | F19: North America | G19: Ministry of Environment | H19: Press release | I19: canada.ca | J19: Minister Guilbeault to make an announcement to support citizen science and protect nature | K19: https://www.canada.ca/en/environment-climate-change/news/2024/02/minister-guilbeault-to-make-an-announcement-to-support-citizen-science-and-protect-nature.html | L19: Climate; Climate Change; Environment; Steven Guilbeault | M19: Yes | N19: 4 | O19: Canada | P19: page metadata | Q19: live | R19: 167 | S19: Steven Guilbeault | T19: Climate; Climate Change; Environment
A20: 2024-02 | B20: 45336 | C20: Pre-withdrawal | D20: Canada | E20: Global North | F20: North America | G20: Ministry of Environment | H20: Press release | I20: canada.ca | J20: Government of Canada invests $3 million in citizen science and open data for birds and biodiversity | K20: https://www.canada.ca/en/environment-climate-change/news/2024/02/government-of-canada-invests-3-million-in-citizen-science-and-open-data-for-birds-and-biodiversity.html | L20: Climate; Climate Change; Environment; Steven Guilbeault | M20: Yes | N20: 4 | O20: Canada | P20: page metadata | Q20: live | R20: 670 | S20: Steven Guilbeault | T20: Climate; Climate Change; Environment
A21: 2024-02 | B21: 45338 | C21: Pre-withdrawal | D21: Canada | E21: Global North | F21: North America | G21: Ministry of Environment | H21: Press release | I21: canada.ca | J21: Minister Guilbeault provides update with new design options for the Clean Electricity Regulations | K21: https://www.canada.ca/en/environment-climate-change/news/2024/02/minister-guilbeault-provides-update-with-new-design-options-for-the-clean-electricity-regulations.html | L21: Climate; Climate Change; Environment; Steven Guilbeault; carbon; emissions; energy; fossil fuel; net zero emissions; transition | M21: Yes | N21: 10 | O21: Canada | P21: page metadata | Q21: live | R21: 890 | S21: Steven Guilbeault | T21: Climate; Climate Change; Environment; carbon; emissions; energy; fossil fuel; net zero emissions; transition
A22: 2024-02 | B22: 45338 | C22: Pre-withdrawal | D22: Canada | E22: Global North | F22: North America | G22: Ministry of Environment | H22: Policy / regulatory | I22: canada.ca | J22: Town of Trenton fined $100,000 for violating the Fisheries Act in Nova Scotia | K22: https://www.canada.ca/en/environment-climate-change/news/2024/02/town-of-trenton-fined-100000-for-violating-the-fisheries-act-in-nova-scotia.html | L22: Climate; Climate Change; Environment | M22: No | N22: 3 | P22: page metadata | Q22: live | R22: 657 | T22: Climate; Climate Change; Environment
A23: 2024-02 | B23: 45342 | C23: Pre-withdrawal | D23: Canada | E23: Global North | F23: North America | G23: Ministry of Environment | H23: Press release | I23: canada.ca | J23: Minister Guilbeault to make a funding announcement supporting affordable home energy retrofits for the City of Peterborough | K23: https://www.canada.ca/en/environment-climate-change/news/2024/02/minister-guilbeault-to-make-a-funding-announcement-to-support-affordable-heating-for-the-city-of-peterborough.html | L23: Climate; Climate Change; Environment; Steven Guilbeault; energy | M23: Yes | N23: 5 | O23: Canada | P23: page metadata | Q23: live | R23: 178 | S23: Steven Guilbeault | T23: Climate; Climate Change; Environment; energy
A24: 2024-02 | B24: 45343 | C24: Pre-withdrawal | D24: Canada | E24: Global North | F24: North America | G24: Ministry of Environment | H24: Press release | I24: canada.ca | J24: Government of Canada to announce a federal investment to support household energy-saving climate action in Newfoundland and Labrador | K24: https://www.canada.ca/en/environment-climate-change/news/2024/02/government-of-canada-to-announce-a-federal-investment-to-support-household-energy-saving-climate-action-in-newfoundland-and-labrador.html | L24: Climate; Climate Change; Environment; Steven Guilbeault; energy | M24: Yes | N24: 5 | O24: Canada | P24: page metadata | Q24: live | R24: 201 | S24: Steven Guilbeault | T24: Climate; Climate Change; Environment; energy
A25: 2024-02 | B25: 45345 | C25: Pre-withdrawal | D25: Canada | E25: Global North | F25: North America | G25: Ministry of Environment | H25: Press release | I25: canada.ca | J25: Federal-provincial agreement allows Newfoundlanders and Labradorians to switch from heating homes with oil to heat pumps and other electric home heating systems | K25: https://www.canada.ca/en/environment-climate-change/news/2024/02/federal-provincial-agreement-allows-newfoundlanders-and-labradorians-to-switch-from-heating-homes-with-oil-to-heat-pumps-and-other-electric-home-he.html | L25: Climate; Climate Change; Environment; Steven Guilbeault; carbon; emissions; energy; greenhouse gas; net zero emissions; transition | M25: Yes | N25: 10 | O25: Canada | P25: page metadata | Q25: live | R25: 1142 | S25: Steven Guilbeault | T25: Climate; Climate Change; Environment; carbon; emissions; energy; greenhouse gas; net zero emissions; transition
A26: 2024-02 | B26: 45345 | C26: Pre-withdrawal | D26: Canada | E26: Global North | F26: North America | G26: Ministry of Environment | H26: Press release | I26: canada.ca | J26: Government of Canada announces draft rules to cut pollutants that cause smog in communities across Canada | K26: https://www.canada.ca/en/environment-climate-change/news/2024/02/government-of-canada-announces-draft-rules-to-cut-pollutants-that-cause-smog-in-communities-across-canada.html | L26: Climate; Climate Change; Environment; Steven Guilbeault; emissions | M26: Yes | N26: 5 | O26: Canada | P26: page metadata | Q26: live | R26: 996 | S26: Steven Guilbeault | T26: Climate; Climate Change; Environment; emissions
A27: 2024-02 | B27: 45345 | C27: Pre-withdrawal | D27: Canada | E27: Global North | F27: North America | G27: Ministry of Environment | H27: Press release | I27: canada.ca | J27: Reduction in the Release of Volatile Organic Compounds (Storage and Loading of Volatile Petroleum Liquids) draft Regulations | K27: https://www.canada.ca/en/environment-climate-change/news/2024/02/reduction-in-the-release-of-volatile-organic-compounds-storage-and-loading-of-volatile-petroleum-liquids-draft-regulations.html | L27: Climate; Climate Change; Environment; carbon; emissions; energy | M27: Yes | N27: 6 | P27: page metadata | Q27: live | R27: 1449 | T27: Climate; Climate Change; Environment; carbon; emissions; energy
A28: 2024-03 | B28: 45352 | C28: Pre-withdrawal | D28: Canada | E28: Global North | F28: North America | G28: Ministry of Environment | H28: Press release | I28: canada.ca | J28: Minister Guilbeault calls for an ambitious plastics treaty at the United Nations Environment Assembly in Kenya | K28: https://www.canada.ca/en/environment-climate-change/news/2024/03/minister-guilbeault-calls-for-an-ambitious-plastics-treaty-at-the-united-nations-environment-assembly-in-kenya.html | L28: COP; Climate; Climate Change; Environment; Steven Guilbeault | M28: Yes | N28: 5 | O28: Canada | P28: page metadata | Q28: live | R28: 785 | S28: Steven Guilbeault | T28: Climate; Climate Change; Environment | U28: COP
A29: 2024-03 | B29: 45352 | C29: Pre-withdrawal | D29: Canada | E29: Global North | F29: North America | G29: Ministry of Environment | H29: Press release | I29: canada.ca | J29: Minister Guilbeault to make a funding announcement to support species at risk and their habitats | K29: https://www.canada.ca/en/environment-climate-change/news/2024/03/minister-guilbeault-to-make-a-funding-announcement-to-support-species-at-risk-and-their-habitats.html | L29: Climate; Climate Change; Environment; Steven Guilbeault | M29: Yes | N29: 4 | O29: Canada | P29: page metadata | Q29: live | R29: 186 | S29: Steven Guilbeault | T29: Climate; Climate Change; Environment
A30: 2024-03 | B30: 45355 | C30: Pre-withdrawal | D30: Canada | E30: Global North | F30: North America | G30: Ministry of Environment | H30: Press release | I30: canada.ca | J30: Empowering key regional environmental groups to protect habitats and species at risk in Quebec and across Canada | K30: https://www.canada.ca/en/environment-climate-change/news/2024/03/empowering-key-regional-environmental-groups-to-protect-habitats-and-species-at-risk-in-quebec-and-across-canada.html | L30: Climate; Climate Change; Environment; Steven Guilbeault | M30: Yes | N30: 4 | O30: Canada | P30: page metadata | Q30: live | R30: 916 | S30: Steven Guilbeault | T30: Climate; Climate Change; Environment
A31: 2024-03 | B31: 45355 | C31: Pre-withdrawal | D31: Canada | E31: Global North | F31: North America | G31: Ministry of Environment | H31: Press release | I31: canada.ca | J31: List of 56 Habitat Stewardship Program for Species at Risk projects 2023–2024 | K31: https://www.canada.ca/en/environment-climate-change/news/2024/03/list-of-56-habitat-stewardship-program-for-species-at-risk-projects-20232024.html | L31: Environment | M31: No | N31: 1 | P31: page metadata | Q31: live | R31: 2647 | T31: Environment
A32: 2024-03 | B32: 45359 | C32: Pre-withdrawal | D32: Canada | E32: Global North | F32: North America | G32: Ministry of Environment | H32: Press release | I32: canada.ca | J32: Governments of Canada and Ontario join together to announce funding and collaboration for conservation areas in Ontario | K32: https://www.canada.ca/en/environment-climate-change/news/2024/03/governments-of-canada-and-ontario-join-together-to-announce-funding-and-collaboration-for-conservation-areas-in-ontario.html | L32: Climate; Climate Change; Environment; Steven Guilbeault | M32: Yes | N32: 4 | O32: Canada | P32: page metadata | Q32: live | R32: 220 | S32: Steven Guilbeault | T32: Climate; Climate Change; Environment
A33: 2024-03 | B33: 45359 | C33: Pre-withdrawal | D33: Canada | E33: Global North | F33: North America | G33: Ministry of Environment | H33: Press release | I33: canada.ca | J33: UPDATE: Minister Guilbeault to travel to New Brunswick to make a funding announcement for a clean electricity project through the Future Electricity Fund | K33: https://www.canada.ca/en/environment-climate-change/news/2024/03/minister-guilbeault-to-travel-to-new-brunswick-to-participate-in-a-ribbon-cutting-ceremony-and-make-a-funding-announcement-for-a-clean-electricity-.html | L33: Climate; Climate Change; Environment; Steven Guilbeault; energy | M33: Yes | N33: 5 | O33: Canada | P33: page metadata | Q33: live | R33: 234 | S33: Steven Guilbeault | T33: Climate; Climate Change; Environment; energy
A34: 2024-03 | B34: 45362 | C34: Pre-withdrawal | D34: Canada | E34: Global North | F34: North America | G34: Ministry of Environment | H34: Press release | I34: canada.ca | J34: Canada and Ontario commit to significant collaboration on shared nature conservation goals | K34: https://www.canada.ca/en/environment-climate-change/news/2024/03/canada-and-ontario-commit-to-significant-collaboration-on-shared-nature-conservation-goals.html | L34: Climate; Climate Change; Environment; Steven Guilbeault; carbon; commitments | M34: Yes | N34: 6 | O34: Canada | P34: page metadata | Q34: live | R34: 1196 | S34: Steven Guilbeault | T34: Climate; Climate Change; Environment; carbon; commitments
A35: 2024-03 | B35: 45362 | C35: Pre-withdrawal | D35: Canada | E35: Global North | F35: North America | G35: Ministry of Environment | H35: Press release | I35: canada.ca | J35: Cutting the ribbon on the largest battery energy storage system in New Brunswick | K35: https://www.canada.ca/en/environment-climate-change/news/2024/03/cutting-the-ribbon-on-the-largest-battery-energy-storage-system-in-new-brunswick.html | L35: Climate; Climate Change; Environment; Steven Guilbeault; emissions; energy; fossil fuel; green; greenhouse gas; renewable energy; transition | M35: Yes | N35: 11 | O35: Canada | P35: page metadata | Q35: live | R35: 942 | S35: Steven Guilbeault | T35: Climate; Climate Change; Environment; emissions; energy; fossil fuel; green; greenhouse gas; renewable energy; transition
A36: 2024-03 | B36: 45362 | C36: Pre-withdrawal | D36: Canada | E36: Global North | F36: North America | G36: Ministry of Environment | H36: Press release | I36: canada.ca | J36: Helping New Brunswickers reduce energy costs, cut pollution | K36: https://www.canada.ca/en/environment-climate-change/news/2024/03/helping-new-brunswickers-reduce-energy-costs-cut-pollution.html | L36: Climate; Climate Change; Environment; Steven Guilbeault; Sustainability; carbon; climate goals; emissions; energy; greenhouse gas; net zero emissions; sustainable energy; transition | M36: Yes | N36: 13 | O36: Canada | P36: page metadata | Q36: live | R36: 1058 | S36: Steven Guilbeault | T36: Climate; Climate Change; Environment; Sustainability; carbon; climate goals; emissions; energy; greenhouse gas; net zero emissions; sustainable energy; transition
A37: 2024-03 | B37: 45362 | C37: Pre-withdrawal | D37: Canada | E37: Global North | F37: North America | G37: Ministry of Environment | H37: Press release | I37: canada.ca | J37: Minister Guilbeault to travel to Nova Scotia to make an announcement regarding a clean energy investment and hold media availabilities | K37: https://www.canada.ca/en/environment-climate-change/news/2024/03/minister-guilbeault-to-travel-to-nova-scotia-to-make-an-announcement-regarding-a-clean-energy-investment-and-hold-media-availabilities.html | L37: Climate; Climate Change; Environment; Steven Guilbeault; energy | M37: Yes | N37: 5 | O37: Canada | P37: page metadata | Q37: live | R37: 213 | S37: Steven Guilbeault | T37: Climate; Climate Change; Environment; energy
A38: 2024-03 | B38: 45363 | C38: Pre-withdrawal | D38: Canada | E38: Global North | F38: North America | G38: Ministry of Environment | H38: Press release | I38: canada.ca | J38: Government of Canada supports Indigenous climate action with new funding stream under the Indigenous Leadership Fund | K38: https://www.canada.ca/en/environment-climate-change/news/2024/03/government-of-canada-supports-indigenous-climate-action-with-new-funding-stream-under-the-indigenous-leadership-fund.html | L38: Climate; Climate Change; Environment; Steven Guilbeault; carbon; emissions; energy; green; greenhouse gas; net zero emissions; renewable energy | M38: Yes | N38: 11 | O38: Canada | P38: page metadata | Q38: live | R38: 662 | S38: Steven Guilbeault | T38: Climate; Climate Change; Environment; carbon; emissions; energy; green; greenhouse gas; net zero emissions; renewable energy
A39: 2024-03 | B39: 45364 | C39: Pre-withdrawal | D39: Canada | E39: Global North | F39: North America | G39: Ministry of Environment | H39: Press release | I39: canada.ca | J39: Government of Canada to deliver final step of major radar modernization project, followed by a site tour | K39: https://www.canada.ca/en/environment-climate-change/news/2024/03/government-of-canada-to-deliver-final-step-of-major-radar-modernization-project-followed-by-a-site-tour.html | L39: Climate; Climate Change; Environment; Steven Guilbeault | M39: Yes | N39: 4 | O39: Canada | P39: page metadata | Q39: live | R39: 263 | S39: Steven Guilbeault | T39: Climate; Climate Change; Environment
A40: 2024-03 | B40: 45365 | C40: Pre-withdrawal | D40: Canada | E40: Global North | F40: North America | G40: Ministry of Environment | H40: Press release | I40: canada.ca | J40: Call for applications for the next Environment and Climate Change Youth Council: A chance to help shape our environmental future | K40: https://www.canada.ca/en/environment-climate-change/news/2024/03/call-for-applications-for-the-next-environment-and-climate-change-youth-council-a-chance-to-help-shape-our-environmental-future.html | L40: Climate; Climate Change; Environment; Steven Guilbeault | M40: Yes | N40: 4 | O40: Canada | P40: page metadata | Q40: live | R40: 697 | S40: Steven Guilbeault | T40: Climate; Climate Change; Environment
...

Sheet 2024-01
A1: Month | B1: Date | C1: Period | D1: Country | E1: North/South | F1: Continent | G1: Source Type | H1: Document Type | I1: Site | J1: Title | K1: URL | L1: Matched Keywords | M1: Strong Match | N1: Keyword Count | O1: Minister/Person Country | P1: Date Source | Q1: Fetched Via | R1: Word Count | S1: Event/Person hits | T1: Adjective Indicators hits | U1: Organizations/Alliances hits | V1: Regulatory Bodies hits
A2: 2024-01 | B2: 45293 | C2: Pre-withdrawal | D2: Canada | E2: Global North | F2: North America | G2: Ministry of Environment | H2: Press release | I2: canada.ca | J2: The Government of Canada is seeking feedback on developing a federal plastics registry to help tackle plastic pollution | K2: https://www.canada.ca/en/environment-climate-change/news/2024/01/the-government-of-canada-is-seeking-feedback-on-developing-a-federal-plastics-registry-to-help-tackle-plastic-pollution.html | L2: Circular; Circular Economy; Climate; Climate Change; Environment; Steven Guilbeault; transition | M2: Yes | N2: 7 | O2: Canada | P2: page metadata | Q2: live | R2: 733 | S2: Steven Guilbeault | T2: Circular; Circular Economy; Climate; Climate Change; Environment; transition
A3: 2024-01 | B3: 45302 | C3: Pre-withdrawal | D3: Canada | E3: Global North | F3: North America | G3: Ministry of Environment | H3: Press release | I3: canada.ca | J3: Environment and Climate Change Canada to hold a technical briefing and media availability related to a winter storm affecting Ontario and Quebec this weekend | K3: https://www.canada.ca/en/environment-climate-change/news/2024/01/environment-and-climate-change-canada-to-hold-a-technical-briefing-and-media-availability-related-to-a-winter-storm-affecting-ontario-and-quebec-th.html | L3: Climate; Climate Change; Environment | M3: No | N3: 3 | P3: page metadata | Q3: live | R3: 223 | T3: Climate; Climate Change; Environment
A4: 2024-01 | B4: 45303 | C4: Pre-withdrawal | D4: Canada | E4: Global North | F4: North America | G4: Ministry of Environment | H4: Press release | I4: canada.ca | J4: Eligible Canadian residents to receive their first pollution pricing rebate of the year | K4: https://www.canada.ca/en/environment-climate-change/news/2024/01/eligible-canadian-residents-to-receive-their-first-pollution-pricing-rebate-of-the-year.html | L4: Climate; Climate Change; Environment; Steven Guilbeault; carbon; emissions; energy; net zero emissions | M4: Yes | N4: 8 | O4: Canada | P4: page metadata | Q4: live | R4: 880 | S4: Steven Guilbeault | T4: Climate; Climate Change; Environment; carbon; emissions; energy; net zero emissions
A5: 2024-01 | B5: 45303 | C5: Pre-withdrawal | D5: Canada | E5: Global North | F5: North America | G5: Ministry of Environment | H5: Press release | I5: canada.ca | J5: Minister Guilbeault to make an announcement to support the Université de Sherbrooke’s work on environmental research | K5: https://www.canada.ca/en/environment-climate-change/news/2024/01/minister-guilbeault-to-make-an-announcement-to-support-the-universite-de-sherbrookes-work-on-environmental-research.html | L5: Climate; Climate Change; Environment; Steven Guilbeault | M5: Yes | N5: 4 | O5: Canada | P5: page metadata | Q5: live | R5: 196 | S5: Steven Guilbeault | T5: Climate; Climate Change; Environment
A6: 2024-01 | B6: 45306 | C6: Pre-withdrawal | D6: Canada | E6: Global North | F6: North America | G6: Ministry of Environment | H6: Press release | I6: canada.ca | J6: Government of Canada announces new investments in environmental research for the Université de Sherbrooke | K6: https://www.canada.ca/en/environment-climate-change/news/2024/01/government-of-canada-announces-new-investments-in-environmental-research-for-the-universite-de-sherbrooke.html | L6: Climate; Climate Change; Environment; Environmental Policy; Steven Guilbeault; carbon; emissions; greenhouse gas | M6: Yes | N6: 8 | O6: Canada | P6: page metadata | Q6: live | R6: 1074 | S6: Steven Guilbeault | T6: Climate; Climate Change; Environment; Environmental Policy; carbon; emissions; greenhouse gas
A7: 2024-01 | B7: 45310 | C7: Pre-withdrawal | D7: Canada | E7: Global North | F7: North America | G7: Ministry of Environment | H7: Press release | I7: canada.ca | J7: Government of Canada to make an announcement on funding for freshwater ecosystem initiatives | K7: https://www.canada.ca/en/environment-climate-change/news/2024/01/government-of-canada-to-make-an-announcement-on-funding-for-freshwater-ecosystem-initiatives.html | L7: Climate; Climate Change; Environment; Steven Guilbeault | M7: Yes | N7: 4 | O7: Canada | P7: page metadata | Q7: live | R7: 159 | S7: Steven Guilbeault | T7: Climate; Climate Change; Environment
A8: 2024-01 | B8: 45313 | C8: Pre-withdrawal | D8: Canada | E8: Global North | F8: North America | G8: Ministry of Environment | H8: Press release | I8: canada.ca | J8: Federal Government opens the door to projects that help keep Canadian fresh water clean and healthy | K8: https://www.canada.ca/en/environment-climate-change/news/2024/01/federal-government-opens-the-door-to-projects-that-help-keep-canadian-fresh-water-clean-and-healthy.html | L8: Climate; Climate Change; Environment; Steven Guilbeault | M8: Yes | N8: 4 | O8: Canada | P8: page metadata | Q8: live | R8: 1070 | S8: Steven Guilbeault | T8: Climate; Climate Change; Environment
A9: 2024-01 | B9: 45313 | C9: Pre-withdrawal | D9: Canada | E9: Global North | F9: North America | G9: Ministry of Environment | H9: Press release | I9: canada.ca | J9: Operation Northern Fur leads to $20,000 in fines and a prohibition order for a Manitoba resident who illegally imported, exported, and transported wildlife | K9: https://www.canada.ca/en/environment-climate-change/news/2024/01/operation-northern-fur-leads-to-20000-in-fines-and-a-prohibition-order-for-a-manitoba-resident-who-illegally-imported-exported-and-transported-wild.html | L9: Climate; Climate Change; Environment | M9: No | N9: 3 | P9: page metadata | Q9: live | R9: 619 | T9: Climate; Climate Change; Environment
A10: 2024-01 | B10: 45317 | C10: Pre-withdrawal | D10: Canada | E10: Global North | F10: North America | G10: Ministry of Environment | H10: Press release | I10: canada.ca | J10: Canada boosts conservation and restoration efforts with investments in 27 new Indigenous-Led Natural Climate Solutions | K10: https://www.canada.ca/en/environment-climate-change/news/2024/01/canada-boosts-conservation-and-restoration-efforts-with-investments-in-27-new-indigenous-led-natural-climate-solutions.html | L10: Climate; Climate Change; Environment; Steven Guilbeault; Sustainability; carbon; emissions; greenhouse gas | M10: Yes | N10: 8 | O10: Canada | P10: page metadata | Q10: live | R10: 1021 | S10: Steven Guilbeault | T10: Climate; Climate Change; Environment; Sustainability; carbon; emissions; greenhouse gas
A11: 2024-01 | B11: 45317 | C11: Pre-withdrawal | D11: Canada | E11: Global North | F11: North America | G11: Ministry of Environment | H11: Press release | I11: canada.ca | J11: List of 27 Indigenous-Led Natural Climate Solutions projects 2023–2024 | K11: https://www.canada.ca/en/environment-climate-change/news/2024/01/list-of-27-indigenous-led-natural-climate-solutions-projects-20232024.html | L11: Climate; Climate Change; Climate change mitigation; carbon; emissions; greenhouse gas | M11: Yes | N11: 6 | P11: page metadata | Q11: live | R11: 1927 | T11: Climate; Climate Change; Climate change mitigation; carbon; emissions; greenhouse gas
A12: 2024-01 | B12: 45317 | C12: Pre-withdrawal | D12: Canada | E12: Global North | F12: North America | G12: Ministry of Environment | H12: Policy / regulatory | I12: canada.ca | J12: North West Redwater Partnership paid $280,428 to the Environmental Damages Fund as part of an environmental protection alternative measures agreement under the Canadian Environmental Protection Act, 1999 | K12: https://www.canada.ca/en/environment-climate-change/news/2024/01/north-west-redwater-partnership-paid-280428-to-the-environmental-damages-fund-as-part-of-an-environmental-protection-alternative-measures-agreement.html | L12: Climate; Climate Change; Environment | M12: No | N12: 3 | P12: page metadata | Q12: live | R12: 691 | T12: Climate; Climate Change; Environment
A13: 2024-01 | B13: 45321 | C13: Pre-withdrawal | D13: Canada | E13: Global North | F13: North America | G13: Ministry of Environment | H13: Press release | I13: canada.ca | J13: Environment and Climate Change Canada Study of Winter Air Pollution in Toronto begins | K13: https://www.canada.ca/en/environment-climate-change/news/2024/01/environment-and-climate-change-canada-study-of-winter-air-pollution-in-toronto-begins.html | L13: Climate; Climate Change; Environment; carbon | M13: Yes | N13: 4 | P13: page metadata | Q13: live | R13: 570 | T13: Climate; Climate Change; Environment; carbon
A14: 2024-01 | B14: 45321 | C14: Pre-withdrawal | D14: Canada | E14: Global North | F14: North America | G14: Ministry of Environment | H14: Press release | I14: canada.ca | J14: Two Quebecers convicted of violating the Migratory Birds Regulations by destroying the nests of endangered Bank Swallows | K14: https://www.canada.ca/en/environment-climate-change/news/2024/01/two-quebecers-convicted-of-violating-the-migratory-birds-regulations-by-destroying-the-nests-of-endangered-bank-swallows.html | L14: Climate; Climate Change; Environment | M14: No | N14: 3 | P14: page metadata | Q14: live | R14: 485 | T14: Climate; Climate Change; Environment
A15: 2024-01 | B15: 45322 | C15: Pre-withdrawal | D15: Canada | E15: Global North | F15: North America | G15: Ministry of Environment | H15: Press release | I15: canada.ca | J15: Forty-two Indigenous-led conservation projects across Canada receive federal funding to protect more nature | K15: https://www.canada.ca/en/environment-climate-change/news/2024/01/forty-two-indigenous-led-conservation-projects-across-canada-receive-federal-funding-to-protect-more-nature.html | L15: Climate; Climate Change; Environment; Steven Guilbeault; Sustainability | M15: Yes | N15: 5 | O15: Canada | P15: page metadata | Q15: live | R15: 1284 | S15: Steven Guilbeault | T15: Climate; Climate Change; Environment; Sustainability

Sheet 2024-02
A1: Month | B1: Date | C1: Period | D1: Country | E1: North/South | F1: Continent | G1: Source Type | H1: Document Type | I1: Site | J1: Title | K1: URL | L1: Matched Keywords | M1: Strong Match | N1: Keyword Count | O1: Minister/Person Country | P1: Date Source | Q1: Fetched Via | R1: Word Count | S1: Event/Person hits | T1: Adjective Indicators hits | U1: Organizations/Alliances hits | V1: Regulatory Bodies hits
A2: 2024-02 | B2: 45324 | C2: Pre-withdrawal | D2: Canada | E2: Global North | F2: North America | G2: Ministry of Environment | H2: Press release | I2: canada.ca | J2: Government of Canada launches public engagement on the 2035 greenhouse gas emissions reduction target | K2: https://www.canada.ca/en/environment-climate-change/news/2024/02/government-of-canada-launches-public-engagement-on-the-2035-greenhouse-gas-emissions-reduction-target.html | L2: Climate; Climate Change; Environment; Paris Agreement; Steven Guilbeault; climate goals; emissions; energy; greenhouse gas; net zero emissions | M2: Yes | N2: 10 | O2: Canada | P2: page metadata | Q2: live | R2: 782 | S2: Steven Guilbeault | T2: Climate; Climate Change; Environment; climate goals; emissions; energy; greenhouse gas; net zero emissions | U2: Paris Agreement
A3: 2024-02 | B3: 45330 | C3: Pre-withdrawal | D3: Canada | E3: Global North | F3: North America | G3: Ministry of Environment | H3: Press release | I3: canada.ca | J3: Canada taking next steps on the right to a healthy environment and environmental justice and racism | K3: https://www.canada.ca/en/environment-climate-change/news/2024/02/canada-taking-next-steps-on-the-right-to-a-healthy-environment-and-environmental-justice-and-racism.html | L3: Climate; Climate Change; Environment | M3: No | N3: 3 | P3: page metadata | Q3: live | R3: 485 | T3: Climate; Climate Change; Environment
A4: 2024-02 | B4: 45330 | C4: Pre-withdrawal | D4: Canada | E4: Global North | F4: North America | G4: Ministry of Environment | H4: Policy / regulatory | I4: canada.ca | J4: Creating a healthy, clean, and sustainable environment for all: Canada consulting on the right to a healthy environment in federal legislation and engaging on environmental justice and racism | K4: https://www.canada.ca/en/environment-climate-change/news/2024/02/creating-a-healthy-clean-and-sustainable-environment-for-all-canada-consulting-on-the-right-to-a-healthy-environment-in-federal-legislation-and-eng.html | L4: Climate; Climate Change; Environment; Steven Guilbeault | M4: Yes | N4: 4 | O4: Canada | P4: page metadata | Q4: live | R4: 776 | S4: Steven Guilbeault | T4: Climate; Climate Change; Environment
A5: 2024-02 | B5: 45335 | C5: Pre-withdrawal | D5: Canada | E5: Global North | F5: North America | G5: Ministry of Environment | H5: Press release | I5: canada.ca | J5: Minister Guilbeault to make an announcement to support citizen science and protect nature | K5: https://www.canada.ca/en/environment-climate-change/news/2024/02/minister-guilbeault-to-make-an-announcement-to-support-citizen-science-and-protect-nature.html | L5: Climate; Climate Change; Environment; Steven Guilbeault | M5: Yes | N5: 4 | O5: Canada | P5: page metadata | Q5: live | R5: 167 | S5: Steven Guilbeault | T5: Climate; Climate Change; Environment
A6: 2024-02 | B6: 45336 | C6: Pre-withdrawal | D6: Canada | E6: Global North | F6: North America | G6: Ministry of Environment | H6: Press release | I6: canada.ca | J6: Government of Canada invests $3 million in citizen science and open data for birds and biodiversity | K6: https://www.canada.ca/en/environment-climate-change/news/2024/02/government-of-canada-invests-3-million-in-citizen-science-and-open-data-for-birds-and-biodiversity.html | L6: Climate; Climate Change; Environment; Steven Guilbeault | M6: Yes | N6: 4 | O6: Canada | P6: page metadata | Q6: live | R6: 670 | S6: Steven Guilbeault | T6: Climate; Climate Change; Environment
A7: 2024-02 | B7: 45338 | C7: Pre-withdrawal | D7: Canada | E7: Global North | F7: North America | G7: Ministry of Environment | H7: Press release | I7: canada.ca | J7: Minister Guilbeault provides update with new design options for the Clean Electricity Regulations | K7: https://www.canada.ca/en/environment-climate-change/news/2024/02/minister-guilbeault-provides-update-with-new-design-options-for-the-clean-electricity-regulations.html | L7: Climate; Climate Change; Environment; Steven Guilbeault; carbon; emissions; energy; fossil fuel; net zero emissions; transition | M7: Yes | N7: 10 | O7: Canada | P7: page metadata | Q7: live | R7: 890 | S7: Steven Guilbeault | T7: Climate; Climate Change; Environment; carbon; emissions; energy; fossil fuel; net zero emissions; transition
A8: 2024-02 | B8: 45338 | C8: Pre-withdrawal | D8: Canada | E8: Global North | F8: North America | G8: Ministry of Environment | H8: Policy / regulatory | I8: canada.ca | J8: Town of Trenton fined $100,000 for violating the Fisheries Act in Nova Scotia | K8: https://www.canada.ca/en/environment-climate-change/news/2024/02/town-of-trenton-fined-100000-for-violating-the-fisheries-act-in-nova-scotia.html | L8: Climate; Climate Change; Environment | M8: No | N8: 3 | P8: page metadata | Q8: live | R8: 657 | T8: Climate; Climate Change; Environment
A9: 2024-02 | B9: 45342 | C9: Pre-withdrawal | D9: Canada | E9: Global North | F9: North America | G9: Ministry of Environment | H9: Press release | I9: canada.ca | J9: Minister Guilbeault to make a funding announcement supporting affordable home energy retrofits for the City of Peterborough | K9: https://www.canada.ca/en/environment-climate-change/news/2024/02/minister-guilbeault-to-make-a-funding-announcement-to-support-affordable-heating-for-the-city-of-peterborough.html | L9: Climate; Climate Change; Environment; Steven Guilbeault; energy | M9: Yes | N9: 5 | O9: Canada | P9: page metadata | Q9: live | R9: 178 | S9: Steven Guilbeault | T9: Climate; Climate Change; Environment; energy
A10: 2024-02 | B10: 45343 | C10: Pre-withdrawal | D10: Canada | E10: Global North | F10: North America | G10: Ministry of Environment | H10: Press release | I10: canada.ca | J10: Government of Canada to announce a federal investment to support household energy-saving climate action in Newfoundland and Labrador | K10: https://www.canada.ca/en/environment-climate-change/news/2024/02/government-of-canada-to-announce-a-federal-investment-to-support-household-energy-saving-climate-action-in-newfoundland-and-labrador.html | L10: Climate; Climate Change; Environment; Steven Guilbeault; energy | M10: Yes | N10: 5 | O10: Canada | P10: page metadata | Q10: live | R10: 201 | S10: Steven Guilbeault | T10: Climate; Climate Change; Environment; energy
A11: 2024-02 | B11: 45345 | C11: Pre-withdrawal | D11: Canada | E11: Global North | F11: North America | G11: Ministry of Environment | H11: Press release | I11: canada.ca | J11: Federal-provincial agreement allows Newfoundlanders and Labradorians to switch from heating homes with oil to heat pumps and other electric home heating systems | K11: https://www.canada.ca/en/environment-climate-change/news/2024/02/federal-provincial-agreement-allows-newfoundlanders-and-labradorians-to-switch-from-heating-homes-with-oil-to-heat-pumps-and-other-electric-home-he.html | L11: Climate; Climate Change; Environment; Steven Guilbeault; carbon; emissions; energy; greenhouse gas; net zero emissions; transition | M11: Yes | N11: 10 | O11: Canada | P11: page metadata | Q11: live | R11: 1142 | S11: Steven Guilbeault | T11: Climate; Climate Change; Environment; carbon; emissions; energy; greenhouse gas; net zero emissions; transition
A12: 2024-02 | B12: 45345 | C12: Pre-withdrawal | D12: Canada | E12: Global North | F12: North America | G12: Ministry of Environment | H12: Press release | I12: canada.ca | J12: Government of Canada announces draft rules to cut pollutants that cause smog in communities across Canada | K12: https://www.canada.ca/en/environment-climate-change/news/2024/02/government-of-canada-announces-draft-rules-to-cut-pollutants-that-cause-smog-in-communities-across-canada.html | L12: Climate; Climate Change; Environment; Steven Guilbeault; emissions | M12: Yes | N12: 5 | O12: Canada | P12: page metadata | Q12: live | R12: 996 | S12: Steven Guilbeault | T12: Climate; Climate Change; Environment; emissions
A13: 2024-02 | B13: 45345 | C13: Pre-withdrawal | D13: Canada | E13: Global North | F13: North America | G13: Ministry of Environment | H13: Press release | I13: canada.ca | J13: Reduction in the Release of Volatile Organic Compounds (Storage and Loading of Volatile Petroleum Liquids) draft Regulations | K13: https://www.canada.ca/en/environment-climate-change/news/2024/02/reduction-in-the-release-of-volatile-organic-compounds-storage-and-loading-of-volatile-petroleum-liquids-draft-regulations.html | L13: Climate; Climate Change; Environment; carbon; emissions; energy | M13: Yes | N13: 6 | P13: page metadata | Q13: live | R13: 1449 | T13: Climate; Climate Change; Environment; carbon; emissions; energy

Sheet 2024-03
A1: Month | B1: Date | C1: Period | D1: Country | E1: North/South | F1: Continent | G1: Source Type | H1: Document Type | I1: Site | J1: Title | K1: URL | L1: Matched Keywords | M1: Strong Match | N1: Keyword Count | O1: Minister/Person Country | P1: Date Source | Q1: Fetched Via | R1: Word Count | S1: Event/Person hits | T1: Adjective Indicators hits | U1: Organizations/Alliances hits | V1: Regulatory Bodies hits
A2: 2024-03 | B2: 45352 | C2: Pre-withdrawal | D2: Canada | E2: Global North | F2: North America | G2: Ministry of Environment | H2: Press release | I2: canada.ca | J2: Minister Guilbeault calls for an ambitious plastics treaty at the United Nations Environment Assembly in Kenya | K2: https://www.canada.ca/en/environment-climate-change/news/2024/03/minister-guilbeault-calls-for-an-ambitious-plastics-treaty-at-the-united-nations-environment-assembly-in-kenya.html | L2: COP; Climate; Climate Change; Environment; Steven Guilbeault | M2: Yes | N2: 5 | O2: Canada | P2: page metadata | Q2: live | R2: 785 | S2: Steven Guilbeault | T2: Climate; Climate Change; Environment | U2: COP
A3: 2024-03 | B3: 45352 | C3: Pre-withdrawal | D3: Canada | E3: Global North | F3: North America | G3: Ministry of Environment | H3: Press release | I3: canada.ca | J3: Minister Guilbeault to make a funding announcement to support species at risk and their habitats | K3: https://www.canada.ca/en/environment-climate-change/news/2024/03/minister-guilbeault-to-make-a-funding-announcement-to-support-species-at-risk-and-their-habitats.html | L3: Climate; Climate Change; Environment; Steven Guilbeault | M3: Yes | N3: 4 | O3: Canada | P3: page metadata | Q3: live | R3: 186 | S3: Steven Guilbeault | T3: Climate; Climate Change; Environment
A4: 2024-03 | B4: 45355 | C4: Pre-withdrawal | D4: Canada | E4: Global North | F4: North America | G4: Ministry of Environment | H4: Press release | I4: canada.ca | J4: Empowering key regional environmental groups to protect habitats and species at risk in Quebec and across Canada | K4: https://www.canada.ca/en/environment-climate-change/news/2024/03/empowering-key-regional-environmental-groups-to-protect-habitats-and-species-at-risk-in-quebec-and-across-canada.html | L4: Climate; Climate Change; Environment; Steven Guilbeault | M4: Yes | N4: 4 | O4: Canada | P4: page metadata | Q4: live | R4: 916 | S4: Steven Guilbeault | T4: Climate; Climate Change; Environment
A5: 2024-03 | B5: 45355 | C5: Pre-withdrawal | D5: Canada | E5: Global North | F5: North America | G5: Ministry of Environment | H5: Press release | I5: canada.ca | J5: List of 56 Habitat Stewardship Program for Species at Risk projects 2023–2024 | K5: https://www.canada.ca/en/environment-climate-change/news/2024/03/list-of-56-habitat-stewardship-program-for-species-at-risk-projects-20232024.html | L5: Environment | M5: No | N5: 1 | P5: page metadata | Q5: live | R5: 2647 | T5: Environment
A6: 2024-03 | B6: 45359 | C6: Pre-withdrawal | D6: Canada | E6: Global North | F6: North America | G6: Ministry of Environment | H6: Press release | I6: canada.ca | J6: Governments of Canada and Ontario join together to announce funding and collaboration for conservation areas in Ontario | K6: https://www.canada.ca/en/environment-climate-change/news/2024/03/governments-of-canada-and-ontario-join-together-to-announce-funding-and-collaboration-for-conservation-areas-in-ontario.html | L6: Climate; Climate Change; Environment; Steven Guilbeault | M6: Yes | N6: 4 | O6: Canada | P6: page metadata | Q6: live | R6: 220 | S6: Steven Guilbeault | T6: Climate; Climate Change; Environment
A7: 2024-03 | B7: 45359 | C7: Pre-withdrawal | D7: Canada | E7: Global North | F7: North America | G7: Ministry of Environment | H7: Press release | I7: canada.ca | J7: UPDATE: Minister Guilbeault to travel to New Brunswick to make a funding announcement for a clean electricity project through the Future Electricity Fund | K7: https://www.canada.ca/en/environment-climate-change/news/2024/03/minister-guilbeault-to-travel-to-new-brunswick-to-participate-in-a-ribbon-cutting-ceremony-and-make-a-funding-announcement-for-a-clean-electricity-.html | L7: Climate; Climate Change; Environment; Steven Guilbeault; energy | M7: Yes | N7: 5 | O7: Canada | P7: page metadata | Q7: live | R7: 234 | S7: Steven Guilbeault | T7: Climate; Climate Change; Environment; energy
A8: 2024-03 | B8: 45362 | C8: Pre-withdrawal | D8: Canada | E8: Global North | F8: North America | G8: Ministry of Environment | H8: Press release | I8: canada.ca | J8: Canada and Ontario commit to significant collaboration on shared nature conservation goals | K8: https://www.canada.ca/en/environment-climate-change/news/2024/03/canada-and-ontario-commit-to-significant-collaboration-on-shared-nature-conservation-goals.html | L8: Climate; Climate Change; Environment; Steven Guilbeault; carbon; commitments | M8: Yes | N8: 6 | O8: Canada | P8: page metadata | Q8: live | R8: 1196 | S8: Steven Guilbeault | T8: Climate; Climate Change; Environment; carbon; commitments
A9: 2024-03 | B9: 45362 | C9: Pre-withdrawal | D9: Canada | E9: Global North | F9: North America | G9: Ministry of Environment | H9: Press release | I9: canada.ca | J9: Cutting the ribbon on the largest battery energy storage system in New Brunswick | K9: https://www.canada.ca/en/environment-climate-change/news/2024/03/cutting-the-ribbon-on-the-largest-battery-energy-storage-system-in-new-brunswick.html | L9: Climate; Climate Change; Environment; Steven Guilbeault; emissions; energy; fossil fuel; green; greenhouse gas; renewable energy; transition | M9: Yes | N9: 11 | O9: Canada | P9: page metadata | Q9: live | R9: 942 | S9: Steven Guilbeault | T9: Climate; Climate Change; Environment; emissions; energy; fossil fuel; green; greenhouse gas; renewable energy; transition
A10: 2024-03 | B10: 45362 | C10: Pre-withdrawal | D10: Canada | E10: Global North | F10: North America | G10: Ministry of Environment | H10: Press release | I10: canada.ca | J10: Helping New Brunswickers reduce energy costs, cut pollution | K10: https://www.canada.ca/en/environment-climate-change/news/2024/03/helping-new-brunswickers-reduce-energy-costs-cut-pollution.html | L10: Climate; Climate Change; Environment; Steven Guilbeault; Sustainability; carbon; climate goals; emissions; energy; greenhouse gas; net zero emissions; sustainable energy; transition | M10: Yes | N10: 13 | O10: Canada | P10: page metadata | Q10: live | R10: 1058 | S10: Steven Guilbeault | T10: Climate; Climate Change; Environment; Sustainability; carbon; climate goals; emissions; energy; greenhouse gas; net zero emissions; sustainable energy; transition
