Workbook

Sheet Monthly Summary
A1: Month | B1: Period | C1: USA | D1: Canada | E1: China | F1: UK | G1: EU | H1: Singapore | I1: India | J1: Hong Kong | K1: New Zealand | L1: South Korea | M1: Total | N1: Strong matches
A2: 2024-01 | B2: Pre-withdrawal | C2: =COUNTIFS('All Articles'!$A:$A,$A2,'All Articles'!$D:$D,C$1) | D2: =COUNTIFS('All Articles'!$A:$A,$A2,'All Articles'!$D:$D,D$1) | E2: =COUNTIFS('All Articles'!$A:$A,$A2,'All Articles'!$D:$D,E$1) | F2: =COUNTIFS('All Articles'!$A:$A,$A2,'All Articles'!$D:$D,F$1) | G2: =COUNTIFS('All Articles'!$A:$A,$A2,'All Articles'!$D:$D,G$1) | H2: =COUNTIFS('All Articles'!$A:$A,$A2,'All Articles'!$D:$D,H$1) | I2: =COUNTIFS('All Articles'!$A:$A,$A2,'All Articles'!$D:$D,I$1) | J2: =COUNTIFS('All Articles'!$A:$A,$A2,'All Articles'!$D:$D,J$1) | ... L2: =COUNTIFS('All Articles'!$A:$A,$A2,'All Articles'!$D:$D,L$1) | M2: =SUM(C2:L2) | N2: =COUNTIFS('All Articles'!$A:$A,$A2,'All Articles'!$K:$K,"Yes")
A3: 2024-02 | B3: Pre-withdrawal | C3: =COUNTIFS('All Articles'!$A:$A,$A3,'All Articles'!$D:$D,C$1) | D3: =COUNTIFS('All Articles'!$A:$A,$A3,'All Articles'!$D:$D,D$1) | E3: =COUNTIFS('All Articles'!$A:$A,$A3,'All Articles'!$D:$D,E$1) | F3: =COUNTIFS('All Articles'!$A:$A,$A3,'All Articles'!$D:$D,F$1) | G3: =COUNTIFS('All Articles'!$A:$A,$A3,'All Articles'!$D:$D,G$1) | H3: =COUNTIFS('All Articles'!$A:$A,$A3,'All Articles'!$D:$D,H$1) | I3: =COUNTIFS('All Articles'!$A:$A,$A3,'All Articles'!$D:$D,I$1) | J3: =COUNTIFS('All Articles'!$A:$A,$A3,'All Articles'!$D:$D,J$1) | ... L3: =COUNTIFS('All Articles'!$A:$A,$A3,'All Articles'!$D:$D,L$1) | M3: =SUM(C3:L3) | N3: =COUNTIFS('All Articles'!$A:$A,$A3,'All Articles'!$K:$K,"Yes")
A4: 2024-03 | B4: Pre-withdrawal | C4: =COUNTIFS('All Articles'!$A:$A,$A4,'All Articles'!$D:$D,C$1) | D4: =COUNTIFS('All Articles'!$A:$A,$A4,'All Articles'!$D:$D,D$1) | E4: =COUNTIFS('All Articles'!$A:$A,$A4,'All Articles'!$D:$D,E$1) | F4: =COUNTIFS('All Articles'!$A:$A,$A4,'All Articles'!$D:$D,F$1) | G4: =COUNTIFS('All Articles'!$A:$A,$A4,'All Articles'!$D:$D,G$1) | H4: =COUNTIFS('All Articles'!$A:$A,$A4,'All Articles'!$D:$D,H$1) | I4: =COUNTIFS('All Articles'!$A:$A,$A4,'All Articles'!$D:$D,I$1) | J4: =COUNTIFS('All Articles'!$A:$A,$A4,'All Articles'!$D:$D,J$1) | ... L4: =COUNTIFS('All Articles'!$A:$A,$A4,'All Articles'!$D:$D,L$1) | M4: =SUM(C4:L4) | N4: =COUNTIFS('All Articles'!$A:$A,$A4,'All Articles'!$K:$K,"Yes")
A5: 2024-04 | B5: Pre-withdrawal | C5: =COUNTIFS('All Articles'!$A:$A,$A5,'All Articles'!$D:$D,C$1) | D5: =COUNTIFS('All Articles'!$A:$A,$A5,'All Articles'!$D:$D,D$1) | E5: =COUNTIFS('All Articles'!$A:$A,$A5,'All Articles'!$D:$D,E$1) | F5: =COUNTIFS('All Articles'!$A:$A,$A5,'All Articles'!$D:$D,F$1) | G5: =COUNTIFS('All Articles'!$A:$A,$A5,'All Articles'!$D:$D,G$1) | H5: =COUNTIFS('All Articles'!$A:$A,$A5,'All Articles'!$D:$D,H$1) | I5: =COUNTIFS('All Articles'!$A:$A,$A5,'All Articles'!$D:$D,I$1) | J5: =COUNTIFS('All Articles'!$A:$A,$A5,'All Articles'!$D:$D,J$1) | ... L5: =COUNTIFS('All Articles'!$A:$A,$A5,'All Articles'!$D:$D,L$1) | M5: =SUM(C5:L5) | N5: =COUNTIFS('All Articles'!$A:$A,$A5,'All Articles'!$K:$K,"Yes")
A6: 2024-05 | B6: Pre-withdrawal | C6: =COUNTIFS('All Articles'!$A:$A,$A6,'All Articles'!$D:$D,C$1) | D6: =COUNTIFS('All Articles'!$A:$A,$A6,'All Articles'!$D:$D,D$1) | E6: =COUNTIFS('All Articles'!$A:$A,$A6,'All Articles'!$D:$D,E$1) | F6: =COUNTIFS('All Articles'!$A:$A,$A6,'All Articles'!$D:$D,F$1) | G6: =COUNTIFS('All Articles'!$A:$A,$A6,'All Articles'!$D:$D,G$1) | H6: =COUNTIFS('All Articles'!$A:$A,$A6,'All Articles'!$D:$D,H$1) | I6: =COUNTIFS('All Articles'!$A:$A,$A6,'All Articles'!$D:$D,I$1) | J6: =COUNTIFS('All Articles'!$A:$A,$A6,'All Articles'!$D:$D,J$1) | ... L6: =COUNTIFS('All Articles'!$A:$A,$A6,'All Articles'!$D:$D,L$1) | M6: =SUM(C6:L6) | N6: =COUNTIFS('All Articles'!$A:$A,$A6,'All Articles'!$K:$K,"Yes")
A7: 2024-06 | B7: Pre-withdrawal | C7: =COUNTIFS('All Articles'!$A:$A,$A7,'All Articles'!$D:$D,C$1) | D7: =COUNTIFS('All Articles'!$A:$A,$A7,'All Articles'!$D:$D,D$1) | E7: =COUNTIFS('All Articles'!$A:$A,$A7,'All Articles'!$D:$D,E$1) | F7: =COUNTIFS('All Articles'!$A:$A,$A7,'All Articles'!$D:$D,F$1) | G7: =COUNTIFS('All Articles'!$A:$A,$A7,'All Articles'!$D:$D,G$1) | H7: =COUNTIFS('All Articles'!$A:$A,$A7,'All Articles'!$D:$D,H$1) | I7: =COUNTIFS('All Articles'!$A:$A,$A7,'All Articles'!$D:$D,I$1) | J7: =COUNTIFS('All Articles'!$A:$A,$A7,'All Articles'!$D:$D,J$1) | ... L7: =COUNTIFS('All Articles'!$A:$A,$A7,'All Articles'!$D:$D,L$1) | M7: =SUM(C7:L7) | N7: =COUNTIFS('All Articles'!$A:$A,$A7,'All Articles'!$K:$K,"Yes")
A8: 2024-07 | B8: Pre-withdrawal | C8: =COUNTIFS('All Articles'!$A:$A,$A8,'All Articles'!$D:$D,C$1) | D8: =COUNTIFS('All Articles'!$A:$A,$A8,'All Articles'!$D:$D,D$1) | E8: =COUNTIFS('All Articles'!$A:$A,$A8,'All Articles'!$D:$D,E$1) | F8: =COUNTIFS('All Articles'!$A:$A,$A8,'All Articles'!$D:$D,F$1) | G8: =COUNTIFS('All Articles'!$A:$A,$A8,'All Articles'!$D:$D,G$1) | H8: =COUNTIFS('All Articles'!$A:$A,$A8,'All Articles'!$D:$D,H$1) | I8: =COUNTIFS('All Articles'!$A:$A,$A8,'All Articles'!$D:$D,I$1) | J8: =COUNTIFS('All Articles'!$A:$A,$A8,'All Articles'!$D:$D,J$1) | ... L8: =COUNTIFS('All Articles'!$A:$A,$A8,'All Articles'!$D:$D,L$1) | M8: =SUM(C8:L8) | N8: =COUNTIFS('All Articles'!$A:$A,$A8,'All Articles'!$K:$K,"Yes")
A9: 2024-08 | B9: Pre-withdrawal | C9: =COUNTIFS('All Articles'!$A:$A,$A9,'All Articles'!$D:$D,C$1) | D9: =COUNTIFS('All Articles'!$A:$A,$A9,'All Articles'!$D:$D,D$1) | E9: =COUNTIFS('All Articles'!$A:$A,$A9,'All Articles'!$D:$D,E$1) | F9: =COUNTIFS('All Articles'!$A:$A,$A9,'All Articles'!$D:$D,F$1) | G9: =COUNTIFS('All Articles'!$A:$A,$A9,'All Articles'!$D:$D,G$1) | H9: =COUNTIFS('All Articles'!$A:$A,$A9,'All Articles'!$D:$D,H$1) | I9: =COUNTIFS('All Articles'!$A:$A,$A9,'All Articles'!$D:$D,I$1) | J9: =COUNTIFS('All Articles'!$A:$A,$A9,'All Articles'!$D:$D,J$1) | ... L9: =COUNTIFS('All Articles'!$A:$A,$A9,'All Articles'!$D:$D,L$1) | M9: =SUM(C9:L9) | N9: =COUNTIFS('All Articles'!$A:$A,$A9,'All Articles'!$K:$K,"Yes")
A10: 2024-09 | B10: Pre-withdrawal | C10: =COUNTIFS('All Articles'!$A:$A,$A10,'All Articles'!$D:$D,C$1) | D10: =COUNTIFS('All Articles'!$A:$A,$A10,'All Articles'!$D:$D,D$1) | E10: =COUNTIFS('All Articles'!$A:$A,$A10,'All Articles'!$D:$D,E$1) | F10: =COUNTIFS('All Articles'!$A:$A,$A10,'All Articles'!$D:$D,F$1) | G10: =COUNTIFS('All Articles'!$A:$A,$A10,'All Articles'!$D:$D,G$1) | H10: =COUNTIFS('All Articles'!$A:$A,$A10,'All Articles'!$D:$D,H$1) | I10: =COUNTIFS('All Articles'!$A:$A,$A10,'All Articles'!$D:$D,I$1) | J10: =COUNTIFS('All Articles'!$A:$A,$A10,'All Articles'!$D:$D,J$1) | ... L10: =COUNTIFS('All Articles'!$A:$A,$A10,'All Articles'!$D:$D,L$1) | M10: =SUM(C10:L10) | N10: =COUNTIFS('All Articles'!$A:$A,$A10,'All Articles'!$K:$K,"Yes")
A11: 2024-10 | B11: Pre-withdrawal | C11: =COUNTIFS('All Articles'!$A:$A,$A11,'All Articles'!$D:$D,C$1) | D11: =COUNTIFS('All Articles'!$A:$A,$A11,'All Articles'!$D:$D,D$1) | E11: =COUNTIFS('All Articles'!$A:$A,$A11,'All Articles'!$D:$D,E$1) | F11: =COUNTIFS('All Articles'!$A:$A,$A11,'All Articles'!$D:$D,F$1) | G11: =COUNTIFS('All Articles'!$A:$A,$A11,'All Articles'!$D:$D,G$1) | H11: =COUNTIFS('All Articles'!$A:$A,$A11,'All Articles'!$D:$D,H$1) | I11: =COUNTIFS('All Articles'!$A:$A,$A11,'All Articles'!$D:$D,I$1) | J11: =COUNTIFS('All Articles'!$A:$A,$A11,'All Articles'!$D:$D,J$1) | ... L11: =COUNTIFS('All Articles'!$A:$A,$A11,'All Articles'!$D:$D,L$1) | M11: =SUM(C11:L11) | N11: =COUNTIFS('All Articles'!$A:$A,$A11,'All Articles'!$K:$K,"Yes")
A12: 2024-11 | B12: Pre-withdrawal | C12: =COUNTIFS('All Articles'!$A:$A,$A12,'All Articles'!$D:$D,C$1) | D12: =COUNTIFS('All Articles'!$A:$A,$A12,'All Articles'!$D:$D,D$1) | E12: =COUNTIFS('All Articles'!$A:$A,$A12,'All Articles'!$D:$D,E$1) | F12: =COUNTIFS('All Articles'!$A:$A,$A12,'All Articles'!$D:$D,F$1) | G12: =COUNTIFS('All Articles'!$A:$A,$A12,'All Articles'!$D:$D,G$1) | H12: =COUNTIFS('All Articles'!$A:$A,$A12,'All Articles'!$D:$D,H$1) | I12: =COUNTIFS('All Articles'!$A:$A,$A12,'All Articles'!$D:$D,I$1) | J12: =COUNTIFS('All Articles'!$A:$A,$A12,'All Articles'!$D:$D,J$1) | ... L12: =COUNTIFS('All Articles'!$A:$A,$A12,'All Articles'!$D:$D,L$1) | M12: =SUM(C12:L12) | N12: =COUNTIFS('All Articles'!$A:$A,$A12,'All Articles'!$K:$K,"Yes")
A13: 2024-12 | B13: Pre-withdrawal | C13: =COUNTIFS('All Articles'!$A:$A,$A13,'All Articles'!$D:$D,C$1) | D13: =COUNTIFS('All Articles'!$A:$A,$A13,'All Articles'!$D:$D,D$1) | E13: =COUNTIFS('All Articles'!$A:$A,$A13,'All Articles'!$D:$D,E$1) | F13: =COUNTIFS('All Articles'!$A:$A,$A13,'All Articles'!$D:$D,F$1) | G13: =COUNTIFS('All Articles'!$A:$A,$A13,'All Articles'!$D:$D,G$1) | H13: =COUNTIFS('All Articles'!$A:$A,$A13,'All Articles'!$D:$D,H$1) | I13: =COUNTIFS('All Articles'!$A:$A,$A13,'All Articles'!$D:$D,I$1) | J13: =COUNTIFS('All Articles'!$A:$A,$A13,'All Articles'!$D:$D,J$1) | ... L13: =COUNTIFS('All Articles'!$A:$A,$A13,'All Articles'!$D:$D,L$1) | M13: =SUM(C13:L13) | N13: =COUNTIFS('All Articles'!$A:$A,$A13,'All Articles'!$K:$K,"Yes")
... A30: 2026-05 | B30: Post-withdrawal | C30: =COUNTIFS('All Articles'!$A:$A,$A30,'All Articles'!$D:$D,C$1) | D30: =COUNTIFS('All Articles'!$A:$A,$A30,'All Articles'!$D:$D,D$1) | E30: =COUNTIFS('All Articles'!$A:$A,$A30,'All Articles'!$D:$D,E$1) | F30: =COUNTIFS('All Articles'!$A:$A,$A30,'All Articles'!$D:$D,F$1) | G30: =COUNTIFS('All Articles'!$A:$A,$A30,'All Articles'!$D:$D,G$1) | H30: =COUNTIFS('All Articles'!$A:$A,$A30,'All Articles'!$D:$D,H$1) | I30: =COUNTIFS('All Articles'!$A:$A,$A30,'All Articles'!$D:$D,I$1) | J30: =COUNTIFS('All Articles'!$A:$A,$A30,'All Articles'!$D:$D,J$1) | ... L30: =COUNTIFS('All Articles'!$A:$A,$A30,'All Articles'!$D:$D,L$1) | M30: =SUM(C30:L30) | N30: =COUNTIFS('All Articles'!$A:$A,$A30,'All Articles'!$K:$K,"Yes")
A31: Total | C31: =SUM(C2:C30) | D31: =SUM(D2:D30) | E31: =SUM(E2:E30) | F31: =SUM(F2:F30) | G31: =SUM(G2:G30) | H31: =SUM(H2:H30) | I31: =SUM(I2:I30) | J31: =SUM(J2:J30) | ... N31: =SUM(N2:N30)
A33: Undated articles | C33: =COUNTIFS('All Articles'!$A:$A,"Undated")
A35: Period | C35: USA | D35: Canada | E35: China | F35: UK | G35: EU | H35: Singapore | I35: India | J35: Hong Kong | K35: New Zealand | L35: South Korea | M35: Total
A36: Pre-withdrawal | C36: =COUNTIFS('All Articles'!$C:$C,$A36,'All Articles'!$D:$D,C$35) | D36: =COUNTIFS('All Articles'!$C:$C,$A36,'All Articles'!$D:$D,D$35) | E36: =COUNTIFS('All Articles'!$C:$C,$A36,'All Articles'!$D:$D,E$35) | F36: =COUNTIFS('All Articles'!$C:$C,$A36,'All Articles'!$D:$D,F$35) | G36: =COUNTIFS('All Articles'!$C:$C,$A36,'All Articles'!$D:$D,G$35) | H36: =COUNTIFS('All Articles'!$C:$C,$A36,'All Articles'!$D:$D,H$35) | I36: =COUNTIFS('All Articles'!$C:$C,$A36,'All Articles'!$D:$D,I$35) | J36: =COUNTIFS('All Articles'!$C:$C,$A36,'All Articles'!$D:$D,J$35) | ... L36: =COUNTIFS('All Articles'!$C:$C,$A36,'All Articles'!$D:$D,L$35) | M36: =SUM(C36:L36)
A37: Transition | C37: =COUNTIFS('All Articles'!$C:$C,$A37,'All Articles'!$D:$D,C$35) | D37: =COUNTIFS('All Articles'!$C:$C,$A37,'All Articles'!$D:$D,D$35) | E37: =COUNTIFS('All Articles'!$C:$C,$A37,'All Articles'!$D:$D,E$35) | F37: =COUNTIFS('All Articles'!$C:$C,$A37,'All Articles'!$D:$D,F$35) | G37: =COUNTIFS('All Articles'!$C:$C,$A37,'All Articles'!$D:$D,G$35) | H37: =COUNTIFS('All Articles'!$C:$C,$A37,'All Articles'!$D:$D,H$35) | I37: =COUNTIFS('All Articles'!$C:$C,$A37,'All Articles'!$D:$D,I$35) | J37: =COUNTIFS('All Articles'!$C:$C,$A37,'All Articles'!$D:$D,J$35) | ... L37: =COUNTIFS('All Articles'!$C:$C,$A37,'All Articles'!$D:$D,L$35) | M37: =SUM(C37:L37)
A38: Post-withdrawal | C38: =COUNTIFS('All Articles'!$C:$C,$A38,'All Articles'!$D:$D,C$35) | D38: =COUNTIFS('All Articles'!$C:$C,$A38,'All Articles'!$D:$D,D$35) | E38: =COUNTIFS('All Articles'!$C:$C,$A38,'All Articles'!$D:$D,E$35) | F38: =COUNTIFS('All Articles'!$C:$C,$A38,'All Articles'!$D:$D,F$35) | G38: =COUNTIFS('All Articles'!$C:$C,$A38,'All Articles'!$D:$D,G$35) | H38: =COUNTIFS('All Articles'!$C:$C,$A38,'All Articles'!$D:$D,H$35) | I38: =COUNTIFS('All Articles'!$C:$C,$A38,'All Articles'!$D:$D,I$35) | J38: =COUNTIFS('All Articles'!$C:$C,$A38,'All Articles'!$D:$D,J$35) | ... L38: =COUNTIFS('All Articles'!$C:$C,$A38,'All Articles'!$D:$D,L$35) | M38: =SUM(C38:L38)

Sheet All Articles
A1: Month | B1: Date | C1: Period | D1: Country | E1: Source Type | F1: Site | G1: Title | H1: URL | I1: Matched Keywords | J1: Keyword Count | K1: Strong Match | L1: Minister/Person Country | M1: Date Source | N1: Word Count | O1: Regulatory Bodies hits | P1: Adjective Indicators hits | Q1: Organizations/Alliances hits | R1: Event/Person hits
A2: 2024-01 | B2: 45298 | C2: Pre-withdrawal | D2: Hong Kong | E2: Govt press release | F2: info.gov.hk | G2: HKETO, Brussels supports Belgian sports event and promotes Hong Kong as a green and dynamic city (with photos) | H2: https://www.info.gov.hk/gia/general/202401/07/P2024010500085.htm | I2: green | J2: 1 | K2: No | M2: url | N2: 215 | P2: green
A3: 2024-01 | B3: 45307 | C3: Pre-withdrawal | D3: New Zealand | E3: Ministry of Environment | F3: environment.govt.nz | G3: Key initiatives | H3: https://environment.govt.nz/what-government-is-doing/key-initiatives/ | I3: Environment | J3: 1 | K3: No | M3: page metadata | N3: 128 | P3: Environment
A4: 2024-01 | B4: 45308 | C4: Pre-withdrawal | D4: Hong Kong | E4: Govt press release | F4: info.gov.hk | G4: 35th Meeting of APEC Expert Group on Energy Data and Analysis held in Hong Kong (with photos) | H4: https://www.info.gov.hk/gia/general/202401/17/P2024011700283.htm | I4: Climate; Climate Change; Environment; Tse Chin-Wan; carbon; carbon emissions; emissions; energy; transition | J4: 9 | K4: Yes | L4: Hong Kong | M4: url | N4: 444 | P4: Climate; Climate Change; Environment; carbon; carbon emissions; emissions; energy; transition | R4: Tse Chin-Wan
A5: 2024-01 | B5: 45310 | C5: Pre-withdrawal | D5: Hong Kong | E5: Govt press release | F5: info.gov.hk | G5: Prefabrication of modules for waste-to-energy facility IÂ·PARK1 completed (with photos) | H5: https://www.info.gov.hk/gia/general/202401/19/P2024011900367.htm | I5: Climate; carbon; energy | J5: 3 | K5: Yes | M5: url | N5: 383 | P5: Climate; carbon; energy
A6: 2024-01 | B6: 45310 | C6: Pre-withdrawal | D6: Hong Kong | E6: Govt press release | F6: info.gov.hk | G6: Public should take precautionary measures against carbon monoxide poisoning | H6: https://www.info.gov.hk/gia/general/202401/19/P2024011900709.htm | I6: carbon | J6: 1 | K6: No | M6: url | N6: 412 | P6: carbon
A7: 2024-01 | B7: 45315 | C7: Pre-withdrawal | D7: Hong Kong | E7: Govt press release | F7: info.gov.hk | G7: Asian Financial Forum explores strategies on sustainable economic development and opportunities of multilateral co-operation (with photos/videos) | H7: https://www.info.gov.hk/gia/general/202401/24/P2024012400767.htm | I7: Climate; Environment; Green Finance; Sustainability; Sustainable Economic Development; green; transition | J7: 7 | K7: Yes | M7: url | N7: 1391 | P7: Climate; Environment; Green Finance; Sustainability; Sustainable Economic Development; green; transition
A8: 2024-01 | B8: 45315 | C8: Pre-withdrawal | D8: Hong Kong | E8: Govt press release | F8: info.gov.hk | G8: LCQ19: Modern waste-to-energy incinerators | H8: https://www.info.gov.hk/gia/general/202401/24/P2024012400274.htm | I8: Temperature; emissions; energy; green; renewable energy | J8: 5 | K8: Yes | M8: url | N8: 1159 | P8: Temperature; emissions; energy; green; renewable energy
A9: 2024-01 | B9: 45316 | C9: Pre-withdrawal | D9: Hong Kong | E9: Govt press release | F9: info.gov.hk | G9: Opening remarks by Permanent Secretary for Financial Services and the Treasury (Financial Services) at Asian Financial Forum Thematic Workshop on Hong Kong - Financing Asia's Real Economy Net-Zero Transition (English only) (with photos) | H9: https://www.info.gov.hk/gia/general/202401/25/P2024012500654.htm | I9: COP; Climate; Climate Change; ESG; Environment; Green Finance; ISSB; Sustainability; Sustainability Reporting; Temperature; carbon; carbon credits; emissions; green; greenhouse gas; transition | J9: 16 | K9: Yes | M9: url | N9: 1907 | O9: ISSB | P9: Climate; Climate Change; ESG; Environment; Green Finance; Sustainability; Sustainability Reporting; Temperature; carbon; carbon credits; emissions; green; greenhouse gas; transition | Q9: COP
A10: 2024-01 | B10: 45317 | C10: Pre-withdrawal | D10: Hong Kong | E10: Govt press release | F10: info.gov.hk | G10: Statement by Environment and Conservation Fund Committee on implementation of municipal solid waste charging scheme in Hong Kong | H10: https://www.info.gov.hk/gia/general/202401/26/P2024012600638.htm | I10: Environment | J10: 1 | K10: No | M10: url | N10: 387 | P10: Environment
A11: 2024-01 | B11: 45320 | C11: Pre-withdrawal | D11: Hong Kong | E11: Govt press release | F11: info.gov.hk | G11: Public should take precautionary measures against carbon monoxide poisoning | H11: https://www.info.gov.hk/gia/general/202401/29/P2024012900732.htm | I11: carbon | J11: 1 | K11: No | M11: url | N11: 393 | P11: carbon
A12: 2024-01 | B12: 45322 | C12: Pre-withdrawal | D12: Hong Kong | E12: Govt press release | F12: info.gov.hk | G12: Statement by Council for Carbon Neutrality and Sustainable Development on implementation of municipal solid waste charging scheme in Hong Kong | H12: https://www.info.gov.hk/gia/general/202401/31/P2024013100350.htm | I12: carbon; carbon emissions; emissions; energy; green | J12: 5 | K12: Yes | M12: url | N12: 356 | P12: carbon; carbon emissions; emissions; energy; green
A13: 2024-02 | B13: 45324 | C13: Pre-withdrawal | D13: Hong Kong | E13: Govt press release | F13: info.gov.hk | G13: Public should take precautionary measures against carbon monoxide poisoning | H13: https://www.info.gov.hk/gia/general/202402/02/P2024020200552.htm | I13: carbon | J13: 1 | K13: No | M13: url | N13: 531 | P13: carbon
A14: 2024-02 | B14: 45324 | C14: Pre-withdrawal | D14: Hong Kong | E14: Govt press release | F14: info.gov.hk | G14: Special operational arrangements for GREEN@COMMUNITY facilities during Lunar New Year holidays | H14: https://www.info.gov.hk/gia/general/202402/02/P2024020200651.htm | I14: Environment; green | J14: 2 | K14: No | M14: url | N14: 315 | P14: Environment; green
A15: 2024-02 | B15: 45327 | C15: Pre-withdrawal | D15: Hong Kong | E15: Govt press release | F15: info.gov.hk | G15: Government urges public to stop using "energy-saving ring" on gas cookers to avoid carbon monoxide poisoning | H15: https://www.info.gov.hk/gia/general/202402/05/P2024020500512.htm | I15: carbon; emissions; energy | J15: 3 | K15: Yes | M15: url | N15: 500 | P15: carbon; emissions; energy
A16: 2024-02 | B16: 45329 | C16: Pre-withdrawal | D16: Hong Kong | E16: Govt press release | F16: info.gov.hk | G16: HKSAR Government's Digital Green Bonds Offering | H16: https://www.info.gov.hk/gia/general/202402/07/P2024020700516.htm | I16: Transparency; green | J16: 2 | K16: No | M16: url | N16: 1273 | P16: Transparency; green
A17: 2024-02 | B17: 45345 | C17: Pre-withdrawal | D17: Hong Kong | E17: Govt press release | F17: info.gov.hk | G17: Qualifying standards for environment-friendly commercial vehicles to remain unchanged from April 2024 to March 2025 | H17: https://www.info.gov.hk/gia/general/202402/23/P2024022300280.htm | I17: Environment; emissions | J17: 2 | K17: No | M17: url | N17: 120 | P17: Environment; emissions
A18: 2024-02 | B18: 45345 | C18: Pre-withdrawal | D18: Hong Kong | E18: Govt press release | F18: info.gov.hk | G18: SEE officiates at opening ceremony of GREEN@TSING YI (with photos) | H18: https://www.info.gov.hk/gia/general/202402/23/P2024022200349.htm | I18: carbon; green | J18: 2 | K18: No | M18: url | N18: 366 | P18: carbon; green
A19: 2024-02 | B19: 45350 | C19: Pre-withdrawal | D19: Hong Kong | E19: Govt press release | F19: info.gov.hk | G19: LCQ12: Operation of the community recycling network GREEN@COMMUNITY | H19: https://www.info.gov.hk/gia/general/202402/28/P2024022800306.htm | I19: Environment; green | J19: 2 | K19: No | M19: url | N19: 2304 | P19: Environment; green
A20: 2024-02 | B20: 45351 | C20: Pre-withdrawal | D20: Hong Kong | E20: Govt press release | F20: info.gov.hk | G20: Government to introduce resolution to set borrowing limit at $500 billion for expanded Government Green Bond Programme and new Infrastructure Bond Programme | H20: https://www.info.gov.hk/gia/general/202402/29/P2024022900260.htm | I20: Climate; Climate Change; Green Finance; green | J20: 4 | K20: No | M20: url | N20: 303 | P20: Climate; Climate Change; Green Finance; green
A21: 2024-02 | B21: 45351 | C21: Pre-withdrawal | D21: Hong Kong | E21: Govt press release | F21: info.gov.hk | G21: Housing Bureau holds seminar themed "Leveraging BuildTech and Green Finance in Public Housing" today to support Green Week (with photos) | H21: https://www.info.gov.hk/gia/general/202402/29/P2024022900351.htm | I21: Green Finance; Sustainability; green | J21: 3 | K21: No | M21: url | N21: 325 | P21: Green Finance; Sustainability; green
... A28: 2026-03 | B28: 46108 | C28: Post-withdrawal | D28: New Zealand | E28: Ministry of Environment | F28: environment.govt.nz | G28: Calculate your emissions | H28: https://environment.govt.nz/what-you-can-do/calculate-your-emissions/ | I28: Environment; emissions | J28: 2 | K28: No | M28: page metadata | N28: 115 | P28: Environment; emissions
A29: 2026-04 | B29: 46121 | C29: Post-withdrawal | D29: Canada | E29: Ministry of Environment | F29: canada.ca | G29: Canada to launch hybrid AI weather model to strengthen forecasting for severe weather | H29: https://www.canada.ca/en/environment-climate-change/news/2026/04/canada-to-launch-hybrid-ai-weather-model-to-strengthen-forecasting-for-severe-weather.html | I29: Climate; Climate Change; Environment; Julie Dabrusin; Temperature | J29: 5 | K29: Yes | L29: Canada | M29: page metadata | N29: 753 | P29: Climate; Climate Change; Environment; Temperature | R29: Julie Dabrusin
A30: 2026-04 | B30: 46128 | C30: Post-withdrawal | D30: Canada | E30: Ministry of Environment | F30: canada.ca | G30: Environment and Climate Change Canada to hold a technical briefing ahead of the Petersberg Climate Dialogue and the G7 Environment Ministers’ Meeting | H30: https://www.canada.ca/en/environment-climate-change/news/2026/04/environment-and-climate-change-canada-to-hold-a-technical-briefing-ahead-of-the-petersberg-climate-dialogue-and-the-g7-environment-ministers-meeting.html | I30: Climate; Climate Change; Environment | J30: 3 | K30: No | M30: page metadata | N30: 187 | P30: Climate; Climate Change; Environment
A31: 2026-04 | B31: 46129 | C31: Post-withdrawal | D31: Canada | E31: Ministry of Environment | F31: canada.ca | G31: Minister Dabrusin to champion climate competitiveness, clean growth, and nature protection at G7 | H31: https://www.canada.ca/en/environment-climate-change/news/2026/04/minister-dabrusin-to-champion-climate-competitiveness-clean-growth-and-nature-protection-at-g7.html | I31: COP; Climate; Climate Change; Environment; Julie Dabrusin; commitments; emissions; energy; transition | J31: 9 | K31: Yes | L31: Canada | M31: page metadata | N31: 852 | P31: Climate; Climate Change; Environment; commitments; emissions; energy; transition | Q31: COP | R31: Julie Dabrusin
A32: 2026-04 | B32: 46135 | C32: Post-withdrawal | D32: Canada | E32: Ministry of Environment | F32: canada.ca | G32: Parliamentary Secretary Myles to highlight Canada’s new nature strategy in Fredericton | H32: https://www.canada.ca/en/environment-climate-change/news/2026/04/parliamentary-secretary-myles-to-highlight-canadas-new-nature-strategy-in-fredericton.html | I32: Climate; Climate Change; Environment; Julie Dabrusin; Nathalie Provost | J32: 5 | K32: Yes | L32: Canada | M32: page metadata | N32: 163 | P32: Climate; Climate Change; Environment | R32: Julie Dabrusin; Nathalie Provost
A33: 2026-04 | B33: 46136 | C33: Post-withdrawal | D33: Canada | E33: Ministry of Environment | F33: canada.ca | G33: A Force of Nature: Canada’s Strategy to Protect Nature | H33: https://www.canada.ca/en/environment-climate-change/news/2026/04/a-force-of-nature-canadas-strategy-to-protect-nature.html | I33: Climate; Climate Change; Environment; Julie Dabrusin; Nathalie Provost; commitments; energy | J33: 7 | K33: Yes | L33: Canada | M33: page metadata | N33: 958 | P33: Climate; Climate Change; Environment; commitments; energy | R33: Julie Dabrusin; Nathalie Provost
A34: 2026-04 | B34: 46136 | C34: Post-withdrawal | D34: Canada | E34: Ministry of Environment | F34: canada.ca | G34: A Force of Nature: Canada’s Strategy to Protect Nature | H34: https://www.canada.ca/en/environment-climate-change/news/2026/04/a-force-of-nature-canadas-strategy-to-protect-nature0.html | I34: carbon; energy | J34: 2 | K34: No | M34: page metadata | N34: 925 | P34: carbon; energy
A35: 2026-04 | B35: 46136 | C35: Post-withdrawal | D35: Canada | E35: Ministry of Environment | F35: canada.ca | G35: Canada and Japan launch new actions to tackle methane, plastic pollution, and biodiversity loss | H35: https://www.canada.ca/en/environment-climate-change/news/2026/04/canada-and-japan-launch-new-actions-to-tackle-methane-plastic-pollution-and-biodiversity-loss.html | I35: COP; Climate; Climate Change; Environment; Julie Dabrusin; Paris Agreement; commitments; emissions; energy; transition | J35: 10 | K35: Yes | L35: Canada | M35: page metadata | N35: 773 | P35: Climate; Climate Change; Environment; commitments; emissions; energy; transition | Q35: COP; Paris Agreement | R35: Julie Dabrusin
A36: 2026-04 | B36: 46136 | C36: Post-withdrawal | D36: Canada | E36: Ministry of Environment | F36: canada.ca | G36: Minister Dabrusin champions a resilient, sustainable future at international environment talks | H36: https://www.canada.ca/en/environment-climate-change/news/2026/04/minister-dabrusin-champions-a-resilient-sustainable-future-at-international-environment-talks.html | I36: CBAM; COP; Climate; Climate Change; Environment; Julie Dabrusin; Paris Agreement; carbon; commitments; emissions; energy; greenhouse gas; renewable energy; transition | J36: 14 | K36: Yes | L36: Canada | M36: page metadata | N36: 1144 | O36: CBAM | P36: Climate; Climate Change; Environment; carbon; commitments; emissions; energy; greenhouse gas; renewable energy; transition | Q36: COP; Paris Agreement | R36: Julie Dabrusin
A37: 2026-05 | B37: 46149 | C37: Post-withdrawal | D37: Canada | E37: Ministry of Environment | F37: canada.ca | G37: Secretary of State (Nature) Nathalie Provost will highlight Canada’s new nature strategy in the Estrie region | H37: https://www.canada.ca/en/environment-climate-change/news/2026/05/secretary-of-state-nature-nathalie-provost-will-highlight-canadas-new-nature-strategy-in-the-estrie-region.html | I37: Climate; Climate Change; Environment; Julie Dabrusin; Nathalie Provost | J37: 5 | K37: Yes | L37: Canada | M37: page metadata | N37: 168 | P37: Climate; Climate Change; Environment | R37: Julie Dabrusin; Nathalie Provost
A38: 2026-05 | B38: 46149 | C38: Post-withdrawal | D38: UK | E38: Ministry of Environment | F38: gov.uk | G38: WF6 1TP, Citron Hygiene UK Limited: environmental surrender issued - EPR/WE0090AB/S004 | H38: https://www.gov.uk/government/publications/wf6-1tp-citron-hygiene-uk-limited-environmental-surrender-issued-eprwe0090abs004 | I38: Environment; emissions | J38: 2 | K38: No | M38: GOV.UK API | N38: 73 | P38: Environment; emissions
A39: 2026-05 | B39: 46150 | C39: Post-withdrawal | D39: Canada | E39: Ministry of Environment | F39: canada.ca | G39: A Force of Nature: Canada’s Strategy to Protect Nature | H39: https://www.canada.ca/en/environment-climate-change/news/2026/05/a-force-of-nature-canadas-strategy-to-protect-nature.html | I39: Climate; Climate Change; Environment; Julie Dabrusin; Nathalie Provost; Sustainable Economy; commitments; energy | J39: 8 | K39: Yes | L39: Canada | M39: page metadata | N39: 1187 | P39: Climate; Climate Change; Environment; Sustainable Economy; commitments; energy | R39: Julie Dabrusin; Nathalie Provost
A40: 2026-05 | B40: 46150 | C40: Post-withdrawal | D40: Canada | E40: Ministry of Environment | F40: canada.ca | G40: Minister Dabrusin’s statement on World Migratory Bird Day | H40: https://www.canada.ca/en/environment-climate-change/news/2026/05/minister-dabrusins-statement-on-world-migratory-bird-day.html | I40: Climate; Climate Change; Environment; Julie Dabrusin; commitments | J40: 5 | K40: Yes | L40: Canada | M40: page metadata | N40: 386 | P40: Climate; Climate Change; Environment; commitments | R40: Julie Dabrusin
A41: 2026-05 | B41: 46150 | C41: Post-withdrawal | D41: Canada | E41: Ministry of Environment | F41: canada.ca | G41: Transport Desgagnés Inc. fined $40,000 for Canada Wildlife Act violations in Nunavut | H41: https://www.canada.ca/en/environment-climate-change/news/2026/05/transport-desgagnes-inc-fined-40000-for-canada-wildlife-act-violations-in-nunavut.html | I41: Climate; Climate Change; Environment | J41: 3 | K41: No | M41: page metadata | N41: 569 | P41: Climate; Climate Change; Environment
A42: 2026-05 | B42: 46153 | C42: Post-withdrawal | D42: Canada | E42: Ministry of Environment | F42: canada.ca | G42: Secretary of State (Nature) Provost will highlight Canada’s new nature strategy in Victoria | H42: https://www.canada.ca/en/environment-climate-change/news/2026/05/secretary-of-state-nature-provost-will-highlight-canadas-new-nature-strategy-in-victoria.html | I42: Climate; Climate Change; Environment; Nathalie Provost | J42: 4 | K42: Yes | L42: Canada | M42: page metadata | N42: 144 | P42: Climate; Climate Change; Environment | R42: Nathalie Provost
A43: 2026-05 | B43: 46154 | C43: Post-withdrawal | D43: Canada | E43: Ministry of Environment | F43: canada.ca | G43: A Force of Nature: Canada’s Strategy to Protect Nature | H43: https://www.canada.ca/en/environment-climate-change/news/2026/05/a-force-of-nature-canadas-strategy-to-protect-nature0.html | I43: Climate; Climate Change; Environment; Julie Dabrusin; Nathalie Provost; commitments; energy | J43: 7 | K43: Yes | L43: Canada | M43: page metadata | N43: 938 | P43: Climate; Climate Change; Environment; commitments; energy | R43: Julie Dabrusin; Nathalie Provost
A44: 2026-05 | B44: 46154 | C44: Post-withdrawal | D44: Canada | E44: Ministry of Environment | F44: canada.ca | G44: Government of Canada supports six new research projects to explore impacts of plastic pollution on Indigenous communities | H44: https://www.canada.ca/en/environment-climate-change/news/2026/05/government-of-canada-supports-six-new-research-projects-to-explore-impacts-of-plastic-pollution-on-indigenous-communities.html | I44: Climate; Climate Change; Environment; Julie Dabrusin | J44: 4 | K44: Yes | L44: Canada | M44: page metadata | N44: 787 | P44: Climate; Climate Change; Environment | R44: Julie Dabrusin
A45: 2026-05 | B45: 46155 | C45: Post-withdrawal | D45: UK | E45: Ministry of Environment | F45: gov.uk | G45: Environment Agency puts brakes on illegal waste site | H45: https://www.gov.uk/government/news/environment-agency-puts-brakes-on-illegal-waste-site | I45: Environment | J45: 1 | K45: No | M45: GOV.UK API | N45: 450 | P45: Environment
A46: 2026-05 | B46: 46156 | C46: Post-withdrawal | D46: UK | E46: Ministry of Environment | F46: gov.uk | G46: Environment Agency Board members' terms extended | H46: https://www.gov.uk/government/news/environment-agency-board-members-terms-extended | I46: Circular; Circular Economy; Climate; Climate Change; Environment; Sustainability; energy; green; transition | J46: 9 | K46: Yes | M46: GOV.UK API | N46: 470 | P46: Circular; Circular Economy; Climate; Climate Change; Environment; Sustainability; energy; green; transition
...

Sheet 2024-01
A1: Month | B1: Date | C1: Period | D1: Country | E1: Source Type | F1: Site | G1: Title | H1: URL | I1: Matched Keywords | J1: Keyword Count | K1: Strong Match | L1: Minister/Person Country | M1: Date Source | N1: Word Count | O1: Regulatory Bodies hits | P1: Adjective Indicators hits | Q1: Organizations/Alliances hits | R1: Event/Person hits
A2: 2024-01 | B2: 45298 | C2: Pre-withdrawal | D2: Hong Kong | E2: Govt press release | F2: info.gov.hk | G2: HKETO, Brussels supports Belgian sports event and promotes Hong Kong as a green and dynamic city (with photos) | H2: https://www.info.gov.hk/gia/general/202401/07/P2024010500085.htm | I2: green | J2: 1 | K2: No | M2: url | N2: 215 | P2: green
A3: 2024-01 | B3: 45307 | C3: Pre-withdrawal | D3: New Zealand | E3: Ministry of Environment | F3: environment.govt.nz | G3: Key initiatives | H3: https://environment.govt.nz/what-government-is-doing/key-initiatives/ | I3: Environment | J3: 1 | K3: No | M3: page metadata | N3: 128 | P3: Environment
A4: 2024-01 | B4: 45308 | C4: Pre-withdrawal | D4: Hong Kong | E4: Govt press release | F4: info.gov.hk | G4: 35th Meeting of APEC Expert Group on Energy Data and Analysis held in Hong Kong (with photos) | H4: https://www.info.gov.hk/gia/general/202401/17/P2024011700283.htm | I4: Climate; Climate Change; Environment; Tse Chin-Wan; carbon; carbon emissions; emissions; energy; transition | J4: 9 | K4: Yes | L4: Hong Kong | M4: url | N4: 444 | P4: Climate; Climate Change; Environment; carbon; carbon emissions; emissions; energy; transition | R4: Tse Chin-Wan
A5: 2024-01 | B5: 45310 | C5: Pre-withdrawal | D5: Hong Kong | E5: Govt press release | F5: info.gov.hk | G5: Prefabrication of modules for waste-to-energy facility IÂ·PARK1 completed (with photos) | H5: https://www.info.gov.hk/gia/general/202401/19/P2024011900367.htm | I5: Climate; carbon; energy | J5: 3 | K5: Yes | M5: url | N5: 383 | P5: Climate; carbon; energy
A6: 2024-01 | B6: 45310 | C6: Pre-withdrawal | D6: Hong Kong | E6: Govt press release | F6: info.gov.hk | G6: Public should take precautionary measures against carbon monoxide poisoning | H6: https://www.info.gov.hk/gia/general/202401/19/P2024011900709.htm | I6: carbon | J6: 1 | K6: No | M6: url | N6: 412 | P6: carbon
A7: 2024-01 | B7: 45315 | C7: Pre-withdrawal | D7: Hong Kong | E7: Govt press release | F7: info.gov.hk | G7: Asian Financial Forum explores strategies on sustainable economic development and opportunities of multilateral co-operation (with photos/videos) | H7: https://www.info.gov.hk/gia/general/202401/24/P2024012400767.htm | I7: Climate; Environment; Green Finance; Sustainability; Sustainable Economic Development; green; transition | J7: 7 | K7: Yes | M7: url | N7: 1391 | P7: Climate; Environment; Green Finance; Sustainability; Sustainable Economic Development; green; transition
A8: 2024-01 | B8: 45315 | C8: Pre-withdrawal | D8: Hong Kong | E8: Govt press release | F8: info.gov.hk | G8: LCQ19: Modern waste-to-energy incinerators | H8: https://www.info.gov.hk/gia/general/202401/24/P2024012400274.htm | I8: Temperature; emissions; energy; green; renewable energy | J8: 5 | K8: Yes | M8: url | N8: 1159 | P8: Temperature; emissions; energy; green; renewable energy
A9: 2024-01 | B9: 45316 | C9: Pre-withdrawal | D9: Hong Kong | E9: Govt press release | F9: info.gov.hk | G9: Opening remarks by Permanent Secretary for Financial Services and the Treasury (Financial Services) at Asian Financial Forum Thematic Workshop on Hong Kong - Financing Asia's Real Economy Net-Zero Transition (English only) (with photos) | H9: https://www.info.gov.hk/gia/general/202401/25/P2024012500654.htm | I9: COP; Climate; Climate Change; ESG; Environment; Green Finance; ISSB; Sustainability; Sustainability Reporting; Temperature; carbon; carbon credits; emissions; green; greenhouse gas; transition | J9: 16 | K9: Yes | M9: url | N9: 1907 | O9: ISSB | P9: Climate; Climate Change; ESG; Environment; Green Finance; Sustainability; Sustainability Reporting; Temperature; carbon; carbon credits; emissions; green; greenhouse gas; transition | Q9: COP
A10: 2024-01 | B10: 45317 | C10: Pre-withdrawal | D10: Hong Kong | E10: Govt press release | F10: info.gov.hk | G10: Statement by Environment and Conservation Fund Committee on implementation of municipal solid waste charging scheme in Hong Kong | H10: https://www.info.gov.hk/gia/general/202401/26/P2024012600638.htm | I10: Environment | J10: 1 | K10: No | M10: url | N10: 387 | P10: Environment
A11: 2024-01 | B11: 45320 | C11: Pre-withdrawal | D11: Hong Kong | E11: Govt press release | F11: info.gov.hk | G11: Public should take precautionary measures against carbon monoxide poisoning | H11: https://www.info.gov.hk/gia/general/202401/29/P2024012900732.htm | I11: carbon | J11: 1 | K11: No | M11: url | N11: 393 | P11: carbon
A12: 2024-01 | B12: 45322 | C12: Pre-withdrawal | D12: Hong Kong | E12: Govt press release | F12: info.gov.hk | G12: Statement by Council for Carbon Neutrality and Sustainable Development on implementation of municipal solid waste charging scheme in Hong Kong | H12: https://www.info.gov.hk/gia/general/202401/31/P2024013100350.htm | I12: carbon; carbon emissions; emissions; energy; green | J12: 5 | K12: Yes | M12: url | N12: 356 | P12: carbon; carbon emissions; emissions; energy; green

Sheet 2024-02
A1: Month | B1: Date | C1: Period | D1: Country | E1: Source Type | F1: Site | G1: Title | H1: URL | I1: Matched Keywords | J1: Keyword Count | K1: Strong Match | L1: Minister/Person Country | M1: Date Source | N1: Word Count | O1: Regulatory Bodies hits | P1: Adjective Indicators hits | Q1: Organizations/Alliances hits | R1: Event/Person hits
A2: 2024-02 | B2: 45324 | C2: Pre-withdrawal | D2: Hong Kong | E2: Govt press release | F2: info.gov.hk | G2: Public should take precautionary measures against carbon monoxide poisoning | H2: https://www.info.gov.hk/gia/general/202402/02/P2024020200552.htm | I2: carbon | J2: 1 | K2: No | M2: url | N2: 531 | P2: carbon
A3: 2024-02 | B3: 45324 | C3: Pre-withdrawal | D3: Hong Kong | E3: Govt press release | F3: info.gov.hk | G3: Special operational arrangements for GREEN@COMMUNITY facilities during Lunar New Year holidays | H3: https://www.info.gov.hk/gia/general/202402/02/P2024020200651.htm | I3: Environment; green | J3: 2 | K3: No | M3: url | N3: 315 | P3: Environment; green
A4: 2024-02 | B4: 45327 | C4: Pre-withdrawal | D4: Hong Kong | E4: Govt press release | F4: info.gov.hk | G4: Government urges public to stop using "energy-saving ring" on gas cookers to avoid carbon monoxide poisoning | H4: https://www.info.gov.hk/gia/general/202402/05/P2024020500512.htm | I4: carbon; emissions; energy | J4: 3 | K4: Yes | M4: url | N4: 500 | P4: carbon; emissions; energy
A5: 2024-02 | B5: 45329 | C5: Pre-withdrawal | D5: Hong Kong | E5: Govt press release | F5: info.gov.hk | G5: HKSAR Government's Digital Green Bonds Offering | H5: https://www.info.gov.hk/gia/general/202402/07/P2024020700516.htm | I5: Transparency; green | J5: 2 | K5: No | M5: url | N5: 1273 | P5: Transparency; green
A6: 2024-02 | B6: 45345 | C6: Pre-withdrawal | D6: Hong Kong | E6: Govt press release | F6: info.gov.hk | G6: Qualifying standards for environment-friendly commercial vehicles to remain unchanged from April 2024 to March 2025 | H6: https://www.info.gov.hk/gia/general/202402/23/P2024022300280.htm | I6: Environment; emissions | J6: 2 | K6: No | M6: url | N6: 120 | P6: Environment; emissions
A7: 2024-02 | B7: 45345 | C7: Pre-withdrawal | D7: Hong Kong | E7: Govt press release | F7: info.gov.hk | G7: SEE officiates at opening ceremony of GREEN@TSING YI (with photos) | H7: https://www.info.gov.hk/gia/general/202402/23/P2024022200349.htm | I7: carbon; green | J7: 2 | K7: No | M7: url | N7: 366 | P7: carbon; green
A8: 2024-02 | B8: 45350 | C8: Pre-withdrawal | D8: Hong Kong | E8: Govt press release | F8: info.gov.hk | G8: LCQ12: Operation of the community recycling network GREEN@COMMUNITY | H8: https://www.info.gov.hk/gia/general/202402/28/P2024022800306.htm | I8: Environment; green | J8: 2 | K8: No | M8: url | N8: 2304 | P8: Environment; green
A9: 2024-02 | B9: 45351 | C9: Pre-withdrawal | D9: Hong Kong | E9: Govt press release | F9: info.gov.hk | G9: Government to introduce resolution to set borrowing limit at $500 billion for expanded Government Green Bond Programme and new Infrastructure Bond Programme | H9: https://www.info.gov.hk/gia/general/202402/29/P2024022900260.htm | I9: Climate; Climate Change; Green Finance; green | J9: 4 | K9: No | M9: url | N9: 303 | P9: Climate; Climate Change; Green Finance; green
A10: 2024-02 | B10: 45351 | C10: Pre-withdrawal | D10: Hong Kong | E10: Govt press release | F10: info.gov.hk | G10: Housing Bureau holds seminar themed "Leveraging BuildTech and Green Finance in Public Housing" today to support Green Week (with photos) | H10: https://www.info.gov.hk/gia/general/202402/29/P2024022900351.htm | I10: Green Finance; Sustainability; green | J10: 3 | K10: No | M10: url | N10: 325 | P10: Green Finance; Sustainability; green

Sheet 2024-03
A1: Month | B1: Date | C1: Period | D1: Country | E1: Source Type | F1: Site | G1: Title | H1: URL | I1: Matched Keywords | J1: Keyword Count | K1: Strong Match | L1: Minister/Person Country | M1: Date Source | N1: Word Count | O1: Regulatory Bodies hits | P1: Adjective Indicators hits | Q1: Organizations/Alliances hits | R1: Event/Person hits
A2: 2024-03 | B2: 45352 | C2: Pre-withdrawal | D2: Hong Kong | E2: Govt press release | F2: info.gov.hk | G2: Conclusion of Hong Kong Green Week-Finance Stream | H2: https://www.info.gov.hk/gia/general/202403/01/P2024030100611.htm | I2: Circular; Circular Economy; Climate; Sustainability; carbon; energy; green; transition | J2: 8 | K2: Yes | M2: url | N2: 360 | P2: Circular; Circular Economy; Climate; Sustainability; carbon; energy; green; transition

Sheet 2024-06
A1: Month | B1: Date | C1: Period | D1: Country | E1: Source Type | F1: Site | G1: Title | H1: URL | I1: Matched Keywords | J1: Keyword Count | K1: Strong Match | L1: Minister/Person Country | M1: Date Source | N1: Word Count | O1: Regulatory Bodies hits | P1: Adjective Indicators hits | Q1: Organizations/Alliances hits | R1: Event/Person hits
A2: 2024-06 | B2: 45467 | C2: Pre-withdrawal | D2: New Zealand | E2: Ministry of Environment | F2: environment.govt.nz | G2: Climate scenarios toolkit | H2: https://environment.govt.nz/what-you-can-do/climate-scenarios-toolkit/ | I2: Climate; Climate Change; Environment | J2: 3 | K2: No | M2: page metadata | N2: 134 | P2: Climate; Climate Change; Environment

Sheet 2024-09
A1: Month | B1: Date | C1: Period | D1: Country | E1: Source Type | F1: Site | G1: Title | H1: URL | I1: Matched Keywords | J1: Keyword Count | K1: Strong Match | L1: Minister/Person Country | M1: Date Source | N1: Word Count | O1: Regulatory Bodies hits | P1: Adjective Indicators hits | Q1: Organizations/Alliances hits | R1: Event/Person hits
A2: 2024-09 | B2: 45553 | C2: Pre-withdrawal | D2: New Zealand | E2: Ministry of Environment | F2: environment.govt.nz | G2: Climate Change | H2: https://environment.govt.nz/facts-and-science/climate-change/ | I2: Climate; Climate Change; Environment | J2: 3 | K2: No | M2: page metadata | N2: 134 | P2: Climate; Climate Change; Environment

Sheet 2024-10
A1: Month | B1: Date | C1: Period | D1: Country | E1: Source Type | F1: Site | G1: Title | H1: URL | I1: Matched Keywords | J1: Keyword Count | K1: Strong Match | L1: Minister/Person Country | M1: Date Source | N1: Word Count | O1: Regulatory Bodies hits | P1: Adjective Indicators hits | Q1: Organizations/Alliances hits | R1: Event/Person hits
A2: 2024-10 | B2: 45574 | C2: Pre-withdrawal | D2: New Zealand | E2: Ministry of Environment | F2: environment.govt.nz | G2: Environmental reporting | H2: https://environment.govt.nz/facts-and-science/environmental-reporting/ | I2: Environment | J2: 1 | K2: No | M2: page metadata | N2: 46 | P2: Environment

Sheet 2025-03
A1: Month | B1: Date | C1: Period | D1: Country | E1: Source Type | F1: Site | G1: Title | H1: URL | I1: Matched Keywords | J1: Keyword Count | K1: Strong Match | L1: Minister/Person Country | M1: Date Source | N1: Word Count | O1: Regulatory Bodies hits | P1: Adjective Indicators hits | Q1: Organizations/Alliances hits | R1: Event/Person hits
A2: 2025-03 | B2: 45729 | C2: Transition | D2: New Zealand | E2: Ministry of Environment | F2: environment.govt.nz | G2: Take action – Te reo Māori | H2: https://environment.govt.nz/what-you-can-do/take-action-landing-page-te-reo/ | I2: Environment | J2: 1 | K2: No | M2: page metadata | N2: 123 | P2: Environment

Sheet 2025-08
A1: Month | B1: Date | C1: Period | D1: Country | E1: Source Type | F1: Site | G1: Title | H1: URL | I1: Matched Keywords | J1: Keyword Count | K1: Strong Match | L1: Minister/Person Country | M1: Date Source | N1: Word Count | O1: Regulatory Bodies hits | P1: Adjective Indicators hits | Q1: Organizations/Alliances hits | R1: Event/Person hits
A2: 2025-08 | B2: 45877 | C2: Transition | D2: New Zealand | E2: Ministry of Environment | F2: environment.govt.nz | G2: Access to Experts | H2: https://environment.govt.nz/what-you-can-do/access-to-experts/ | I2: Environment | J2: 1 | K2: No | M2: page metadata | N2: 115 | P2: Environment

Sheet 2026-03
A1: Month | B1: Date | C1: Period | D1: Country | E1: Source Type | F1: Site | G1: Title | H1: URL | I1: Matched Keywords | J1: Keyword Count | K1: Strong Match | L1: Minister/Person Country | M1: Date Source | N1: Word Count | O1: Regulatory Bodies hits | P1: Adjective Indicators hits | Q1: Organizations/Alliances hits | R1: Event/Person hits
A2: 2026-03 | B2: 46108 | C2: Post-withdrawal | D2: New Zealand | E2: Ministry of Environment | F2: environment.govt.nz | G2: Calculate your emissions | H2: https://environment.govt.nz/what-you-can-do/calculate-your-emissions/ | I2: Environment; emissions | J2: 2 | K2: No | M2: page metadata | N2: 115 | P2: Environment; emissions

Sheet 2026-04
A1: Month | B1: Date | C1: Period | D1: Country | E1: Source Type | F1: Site | G1: Title | H1: URL | I1: Matched Keywords | J1: Keyword Count | K1: Strong Match | L1: Minister/Person Country | M1: Date Source | N1: Word Count | O1: Regulatory Bodies hits | P1: Adjective Indicators hits | Q1: Organizations/Alliances hits | R1: Event/Person hits
A2: 2026-04 | B2: 46121 | C2: Post-withdrawal | D2: Canada | E2: Ministry of Environment | F2: canada.ca | G2: Canada to launch hybrid AI weather model to strengthen forecasting for severe weather | H2: https://www.canada.ca/en/environment-climate-change/news/2026/04/canada-to-launch-hybrid-ai-weather-model-to-strengthen-forecasting-for-severe-weather.html | I2: Climate; Climate Change; Environment; Julie Dabrusin; Temperature | J2: 5 | K2: Yes | L2: Canada | M2: page metadata | N2: 753 | P2: Climate; Climate Change; Environment; Temperature | R2: Julie Dabrusin
A3: 2026-04 | B3: 46128 | C3: Post-withdrawal | D3: Canada | E3: Ministry of Environment | F3: canada.ca | G3: Environment and Climate Change Canada to hold a technical briefing ahead of the Petersberg Climate Dialogue and the G7 Environment Ministers’ Meeting | H3: https://www.canada.ca/en/environment-climate-change/news/2026/04/environment-and-climate-change-canada-to-hold-a-technical-briefing-ahead-of-the-petersberg-climate-dialogue-and-the-g7-environment-ministers-meeting.html | I3: Climate; Climate Change; Environment | J3: 3 | K3: No | M3: page metadata | N3: 187 | P3: Climate; Climate Change; Environment
A4: 2026-04 | B4: 46129 | C4: Post-withdrawal | D4: Canada | E4: Ministry of Environment | F4: canada.ca | G4: Minister Dabrusin to champion climate competitiveness, clean growth, and nature protection at G7 | H4: https://www.canada.ca/en/environment-climate-change/news/2026/04/minister-dabrusin-to-champion-climate-competitiveness-clean-growth-and-nature-protection-at-g7.html | I4: COP; Climate; Climate Change; Environment; Julie Dabrusin; commitments; emissions; energy; transition | J4: 9 | K4: Yes | L4: Canada | M4: page metadata | N4: 852 | P4: Climate; Climate Change; Environment; commitments; emissions; energy; transition | Q4: COP | R4: Julie Dabrusin
A5: 2026-04 | B5: 46135 | C5: Post-withdrawal | D5: Canada | E5: Ministry of Environment | F5: canada.ca | G5: Parliamentary Secretary Myles to highlight Canada’s new nature strategy in Fredericton | H5: https://www.canada.ca/en/environment-climate-change/news/2026/04/parliamentary-secretary-myles-to-highlight-canadas-new-nature-strategy-in-fredericton.html | I5: Climate; Climate Change; Environment; Julie Dabrusin; Nathalie Provost | J5: 5 | K5: Yes | L5: Canada | M5: page metadata | N5: 163 | P5: Climate; Climate Change; Environment | R5: Julie Dabrusin; Nathalie Provost
A6: 2026-04 | B6: 46136 | C6: Post-withdrawal | D6: Canada | E6: Ministry of Environment | F6: canada.ca | G6: A Force of Nature: Canada’s Strategy to Protect Nature | H6: https://www.canada.ca/en/environment-climate-change/news/2026/04/a-force-of-nature-canadas-strategy-to-protect-nature.html | I6: Climate; Climate Change; Environment; Julie Dabrusin; Nathalie Provost; commitments; energy | J6: 7 | K6: Yes | L6: Canada | M6: page metadata | N6: 958 | P6: Climate; Climate Change; Environment; commitments; energy | R6: Julie Dabrusin; Nathalie Provost
A7: 2026-04 | B7: 46136 | C7: Post-withdrawal | D7: Canada | E7: Ministry of Environment | F7: canada.ca | G7: A Force of Nature: Canada’s Strategy to Protect Nature | H7: https://www.canada.ca/en/environment-climate-change/news/2026/04/a-force-of-nature-canadas-strategy-to-protect-nature0.html | I7: carbon; energy | J7: 2 | K7: No | M7: page metadata | N7: 925 | P7: carbon; energy
A8: 2026-04 | B8: 46136 | C8: Post-withdrawal | D8: Canada | E8: Ministry of Environment | F8: canada.ca | G8: Canada and Japan launch new actions to tackle methane, plastic pollution, and biodiversity loss | H8: https://www.canada.ca/en/environment-climate-change/news/2026/04/canada-and-japan-launch-new-actions-to-tackle-methane-plastic-pollution-and-biodiversity-loss.html | I8: COP; Climate; Climate Change; Environment; Julie Dabrusin; Paris Agreement; commitments; emissions; energy; transition | J8: 10 | K8: Yes | L8: Canada | M8: page metadata | N8: 773 | P8: Climate; Climate Change; Environment; commitments; emissions; energy; transition | Q8: COP; Paris Agreement | R8: Julie Dabrusin
A9: 2026-04 | B9: 46136 | C9: Post-withdrawal | D9: Canada | E9: Ministry of Environment | F9: canada.ca | G9: Minister Dabrusin champions a resilient, sustainable future at international environment talks | H9: https://www.canada.ca/en/environment-climate-change/news/2026/04/minister-dabrusin-champions-a-resilient-sustainable-future-at-international-environment-talks.html | I9: CBAM; COP; Climate; Climate Change; Environment; Julie Dabrusin; Paris Agreement; carbon; commitments; emissions; energy; greenhouse gas; renewable energy; transition | J9: 14 | K9: Yes | L9: Canada | M9: page metadata | N9: 1144 | O9: CBAM | P9: Climate; Climate Change; Environment; carbon; commitments; emissions; energy; greenhouse gas; renewable energy; transition | Q9: COP; Paris Agreement | R9: Julie Dabrusin

Sheet 2026-05
A1: Month | B1: Date | C1: Period | D1: Country | E1: Source Type | F1: Site | G1: Title | H1: URL | I1: Matched Keywords | J1: Keyword Count | K1: Strong Match | L1: Minister/Person Country | M1: Date Source | N1: Word Count | O1: Regulatory Bodies hits | P1: Adjective Indicators hits | Q1: Organizations/Alliances hits | R1: Event/Person hits
A2: 2026-05 | B2: 46149 | C2: Post-withdrawal | D2: Canada | E2: Ministry of Environment | F2: canada.ca | G2: Secretary of State (Nature) Nathalie Provost will highlight Canada’s new nature strategy in the Estrie region | H2: https://www.canada.ca/en/environment-climate-change/news/2026/05/secretary-of-state-nature-nathalie-provost-will-highlight-canadas-new-nature-strategy-in-the-estrie-region.html | I2: Climate; Climate Change; Environment; Julie Dabrusin; Nathalie Provost | J2: 5 | K2: Yes | L2: Canada | M2: page metadata | N2: 168 | P2: Climate; Climate Change; Environment | R2: Julie Dabrusin; Nathalie Provost
A3: 2026-05 | B3: 46149 | C3: Post-withdrawal | D3: UK | E3: Ministry of Environment | F3: gov.uk | G3: WF6 1TP, Citron Hygiene UK Limited: environmental surrender issued - EPR/WE0090AB/S004 | H3: https://www.gov.uk/government/publications/wf6-1tp-citron-hygiene-uk-limited-environmental-surrender-issued-eprwe0090abs004 | I3: Environment; emissions | J3: 2 | K3: No | M3: GOV.UK API | N3: 73 | P3: Environment; emissions
A4: 2026-05 | B4: 46150 | C4: Post-withdrawal | D4: Canada | E4: Ministry of Environment | F4: canada.ca | G4: A Force of Nature: Canada’s Strategy to Protect Nature | H4: https://www.canada.ca/en/environment-climate-change/news/2026/05/a-force-of-nature-canadas-strategy-to-protect-nature.html | I4: Climate; Climate Change; Environment; Julie Dabrusin; Nathalie Provost; Sustainable Economy; commitments; energy | J4: 8 | K4: Yes | L4: Canada | M4: page metadata | N4: 1187 | P4: Climate; Climate Change; Environment; Sustainable Economy; commitments; energy | R4: Julie Dabrusin; Nathalie Provost
A5: 2026-05 | B5: 46150 | C5: Post-withdrawal | D5: Canada | E5: Ministry of Environment | F5: canada.ca | G5: Minister Dabrusin’s statement on World Migratory Bird Day | H5: https://www.canada.ca/en/environment-climate-change/news/2026/05/minister-dabrusins-statement-on-world-migratory-bird-day.html | I5: Climate; Climate Change; Environment; Julie Dabrusin; commitments | J5: 5 | K5: Yes | L5: Canada | M5: page metadata | N5: 386 | P5: Climate; Climate Change; Environment; commitments | R5: Julie Dabrusin
A6: 2026-05 | B6: 46150 | C6: Post-withdrawal | D6: Canada | E6: Ministry of Environment | F6: canada.ca | G6: Transport Desgagnés Inc. fined $40,000 for Canada Wildlife Act violations in Nunavut | H6: https://www.canada.ca/en/environment-climate-change/news/2026/05/transport-desgagnes-inc-fined-40000-for-canada-wildlife-act-violations-in-nunavut.html | I6: Climate; Climate Change; Environment | J6: 3 | K6: No | M6: page metadata | N6: 569 | P6: Climate; Climate Change; Environment
A7: 2026-05 | B7: 46153 | C7: Post-withdrawal | D7: Canada | E7: Ministry of Environment | F7: canada.ca | G7: Secretary of State (Nature) Provost will highlight Canada’s new nature strategy in Victoria | H7: https://www.canada.ca/en/environment-climate-change/news/2026/05/secretary-of-state-nature-provost-will-highlight-canadas-new-nature-strategy-in-victoria.html | I7: Climate; Climate Change; Environment; Nathalie Provost | J7: 4 | K7: Yes | L7: Canada | M7: page metadata | N7: 144 | P7: Climate; Climate Change; Environment | R7: Nathalie Provost
A8: 2026-05 | B8: 46154 | C8: Post-withdrawal | D8: Canada | E8: Ministry of Environment | F8: canada.ca | G8: A Force of Nature: Canada’s Strategy to Protect Nature | H8: https://www.canada.ca/en/environment-climate-change/news/2026/05/a-force-of-nature-canadas-strategy-to-protect-nature0.html | I8: Climate; Climate Change; Environment; Julie Dabrusin; Nathalie Provost; commitments; energy | J8: 7 | K8: Yes | L8: Canada | M8: page metadata | N8: 938 | P8: Climate; Climate Change; Environment; commitments; energy | R8: Julie Dabrusin; Nathalie Provost
A9: 2026-05 | B9: 46154 | C9: Post-withdrawal | D9: Canada | E9: Ministry of Environment | F9: canada.ca | G9: Government of Canada supports six new research projects to explore impacts of plastic pollution on Indigenous communities | H9: https://www.canada.ca/en/environment-climate-change/news/2026/05/government-of-canada-supports-six-new-research-projects-to-explore-impacts-of-plastic-pollution-on-indigenous-communities.html | I9: Climate; Climate Change; Environment; Julie Dabrusin | J9: 4 | K9: Yes | L9: Canada | M9: page metadata | N9: 787 | P9: Climate; Climate Change; Environment | R9: Julie Dabrusin
A10: 2026-05 | B10: 46155 | C10: Post-withdrawal | D10: UK | E10: Ministry of Environment | F10: gov.uk | G10: Environment Agency puts brakes on illegal waste site | H10: https://www.gov.uk/government/news/environment-agency-puts-brakes-on-illegal-waste-site | I10: Environment | J10: 1 | K10: No | M10: GOV.UK API | N10: 450 | P10: Environment
A11: 2026-05 | B11: 46156 | C11: Post-withdrawal | D11: UK | E11: Ministry of Environment | F11: gov.uk | G11: Environment Agency Board members' terms extended | H11: https://www.gov.uk/government/news/environment-agency-board-members-terms-extended | I11: Circular; Circular Economy; Climate; Climate Change; Environment; Sustainability; energy; green; transition | J11: 9 | K11: Yes | M11: GOV.UK API | N11: 470 | P11: Circular; Circular Economy; Climate; Climate Change; Environment; Sustainability; energy; green; transition
A12: 2026-05 | B12: 46157 | C12: Post-withdrawal | D12: Canada | E12: Ministry of Environment | F12: canada.ca | G12: ArcelorMittal Exploitation Minière Canada s.e.n.c. fined $100 million for violating the Fisheries Act through illegal deposits of deleterious substances | H12: https://www.canada.ca/en/environment-climate-change/news/2026/05/arcelormittal-exploitation-miniere-canada-senc-fined-100-million-for-violating-the-fisheries-act-through-illegal-deposits-of-deleterious-substances.html | I12: Climate; Climate Change; Environment | J12: 3 | K12: No | M12: page metadata | N12: 730 | P12: Climate; Climate Change; Environment
A13: 2026-05 | B13: 46157 | C13: Post-withdrawal | D13: New Zealand | E13: Ministry of Environment | F13: environment.govt.nz | G13: Assessments for carbon removals | H13: https://environment.govt.nz/what-you-can-do/assessments-for-carbon-removals/ | I13: Climate; Climate Change; carbon; emissions; greenhouse gas | J13: 5 | K13: Yes | M13: page metadata | N13: 643 | P13: Climate; Climate Change; carbon; emissions; greenhouse gas
A14: 2026-05 | B14: 46157 | C14: Post-withdrawal | D14: UK | E14: Ministry of Environment | F14: gov.uk | G14: Environment Agency issues Angus Fire permit variation | H14: https://www.gov.uk/government/news/environment-agency-issues-angus-fire-permit-variation | I14: Environment | J14: 1 | K14: No | M14: GOV.UK API | N14: 532 | P14: Environment
A15: 2026-05 | B15: 46157 | C15: Post-withdrawal | D15: UK | E15: Ministry of Environment | F15: gov.uk | G15: Farmer fined after pollution kills a thousand fish | H15: https://www.gov.uk/government/news/farmer-fined-after-pollution-kills-a-thousand-fish | I15: Environment | J15: 1 | K15: No | M15: GOV.UK API | N15: 428 | P15: Environment
A16: 2026-05 | B16: 46159 | C16: Post-withdrawal | D16: UK | E16: Ministry of Environment | F16: gov.uk | G16: New reforms to stop waste criminals from exploiting loopholes | H16: https://www.gov.uk/government/news/new-reforms-to-stop-waste-criminals-from-exploiting-loopholes | I16: Environment | J16: 1 | K16: No | M16: GOV.UK API | N16: 911 | P16: Environment
A17: 2026-05 | B17: 46160 | C17: Post-withdrawal | D17: UK | E17: Ministry of Environment | F17: gov.uk | G17: BH23 6BG, Eco Sustainable Solutions Limited: environmental permit issued - EPR/GP3793FY/V019 | H17: https://www.gov.uk/government/publications/bh23-6bg-eco-sustainable-solutions-limited-environmental-permit-issued-eprgp3793fyv019 | I17: Environment; emissions | J17: 2 | K17: No | M17: GOV.UK API | N17: 77 | P17: Environment; emissions
A18: 2026-05 | B18: 46160 | C18: Post-withdrawal | D18: UK | E18: Ministry of Environment | F18: gov.uk | G18: Have your say on proposed change to permit at Hinkley Point C | H18: https://www.gov.uk/government/news/have-your-say-on-proposed-change-to-permit-at-hinkley-point-c | I18: Environment | J18: 1 | K18: No | M18: GOV.UK API | N18: 424 | P18: Environment
